Workbook

Sheet 高净值
A1: 账户规划 | B1: 匹配策略 | C1: 工具-BLOCK | D1: 参考基准 | E1: 入池或模块筛选标准 | F1: 工具示例
A2: 增值 | B2: 对标大势 | C2: 1.精品私募 2.公募池（涵盖11个板块33只基金-主动*10，被动*23） 3.投顾组合（e.g.奇点1号、2号） | D2: 科创创业50等权 （932381.CSI） | E2: 1、风格明确的高仓/满仓运作的工具化产品 2、受益于全球AI供应链景气（AI基建）或受益于国产替代景气（半导体材料、设备、芯片等） 3、符合国家“十五五”战略发展方向 4、采用景气度趋势投资等策略跟踪产业方向 5、私募管理人风格鲜明且稳定，业绩前1/5 | F2: 1.全球人工智能指数、龙旗科技创新 2.同大众版工具库
B3: 对标市场 | C3: 1.精品私募 2.宽基指基或指增基金 | D3: 中证800 （000906.sh） | E3: 1.指数-跟踪误差低、规模头部前1/5 2.指增-α稳定且始终处于同类前1/3 | F3: 1.掘金宝系列、龙翔、龙腾、麒麟（宝）系列 2.同大众版工具库
A6: 生息 | B6: 债券生息 | C6: 1.精品私募 2.短期及中长期债券公募指基 | D6: 中债新综合指数 （CBA00101.CB） | E6: 1.管理人、规模、流动性 2.良好的风险治理架构 | F6: 1.合晟同晖3号、岚湖、利位优势轮动等 2.同大众版工具库
B11: 波动生息 | C11: 1.金兔、青鸾系列 2.投顾组合（e.g.梧桐） | D11: LC+4% | E11: 结构化策略 | F11: 金兔系列、青鸾
B12: 低波多资产 | C12: 1.魔方系列 2.投顾组合（e.g.百灵） | D12: 中证MARP （930929.CSI） | E12: 策略稳定、业绩可追溯 | F12: 魔方系列
B13: 低波多策略 | C13: CTA及中性套利等多策略 | D13: LC+4% | E13: 策略稳定、业绩可追溯 | F13: 千象、聚金宝、伯乐5号、锐联多元化、博润银泰稳健等
A14: 保障 | B14: 保身家 | C14: 寿险、杠杆寿 | D14: -- | E14: -- | F14: 杠杆寿系列

Sheet 超高净
A1: 账户规划 | B1: 匹配策略 | C1: 工具-BLOCK | D1: 参考基准 | E1: 入池或模块筛选标准 | F1: 工具示例
A2: 增值 | B2: 对标大势 | C2: 1.精品私募 2.公募池（涵盖11个板块33只基金-主动*10，被动*23） 3.投顾组合（e.g.奇点1号、2号） 4、私募股权基金 | D2: 科创创业50等权 （932381.CSI） | E2: 1、风格明确的高仓/满仓运作的工具化产品 2、受益于全球AI供应链景气（AI基建）或受益于国产替代景气（半导体材料、设备、芯片等） 3、符合国家“十五五”战略发展方向 4、采用景气度趋势投资等策略跟踪产业方向 5、私募管理人风格鲜明且稳定，业绩前1/5 | F2: 1.高景气策略（私募）、全球人工智能指数、龙旗科技创新 2.同大众版工具库
B3: 对标市场 | C3: 1.精品私募 2.宽基指基或指增基金 | D3: 中证800 （000906.SH） | E3: 1.指数-跟踪误差低、规模头部前1/5 2.指增-α稳定且始终处于同类前1/3 | F3: 1.掘金宝系列、龙翔、龙腾、麒麟（宝）系列 2.同大众版工具库
A6: 生息 | B6: 债券生息 | C6: 1.精品私募 2.短期及中长期债券公募指基 | D6: 中债新综合指数 （CBA00101.CB） | E6: 1.管理人、规模、流动性 2.良好的风险治理架构 | F6: 1.合晟同晖3号、岚湖、利位优势轮动等 2.同大众版工具库
B11: 波动生息 | C11: 1.金兔、青鸾系列 2.投顾组合（e.g.梧桐） | D11: LC+4% | E11: 结构化策略 | F11: 金兔系列、青鸾
B12: 低波多资产 | C12: 1.魔方系列 2.投顾组合（e.g.百灵） | D12: 中证MARP （930929.CSI） | E12: 策略稳定、业绩可追溯 | F12: 魔方系列
B13: 低波多策略 | C13: CTA及中性套利等多策略 | D13: LC+4% | E13: 策略稳定、业绩可追溯 | F13: 千象、聚金宝、伯乐5号、锐联多元化、博润银泰稳健等
B14: 长期生息 | C14: 实物资产、储蓄分红 | D14: ？ | E14: ？ | F14: -
A15: 保障 | B15: 保身家 | C15: 寿险、杠杆寿 | D15: -- | E15: -- | F15: 杠杆寿系列

Sheet 大众
A1: 账户规划 | B1: 匹配策略 | C1: 工具-BLOCK | D1: 参考基准 | E1: 入池或模块筛选标准 | F1: 工具示例
A2: 增值 | B2: 对标大势 | C2: 1. 公募池（涵盖11个方向33只基金-主动*10，被动*23） 2. 投顾组合（e.g.奇点1号、2号？） | D2: 科创创业50等权 （932381.CSI） | E2: 1、风格明确的高仓/满仓运作的工具化产品 2、受益于全球AI供应链景气（AI基建）或受益于国产替代景气（半导体材料、设备、芯片等） 3、符合国家“十五五”战略发展方向 4、采用景气度趋势投资等策略跟踪产业方向 | F2: 1.见产业趋势池-公募 2.自主构建“奇点”投顾组合系列
B3: 对标市场 | C3: 1.宽基指基或指增基金 2.投顾组合（e.g.瑞鹤） | D3: 中证800 （000906.SH） | E3: 1.指数-跟踪误差低、规模头部前1/5 2.指增-α稳定且始终处于同类前1/3 | F3: 国泰海通中证500指数增强A（014155.OF）
F4: 汇添富中证1000指数增强A（017953.OF）
F6: 瑞鹤指增宝（中证1000增强）
A7: 生息 | B7: 债券生息 | C7: 1.短期及中长期债券公募指基 2、投顾组合（e.g.嘉蝠） | D7: 中债新综合指数 （CBA00101.CB） | E7: 1.管理人、规模、流动性 2.α稳定 | F7: 综合债-易方达中债新综指(LOF)A（161119.OF）
F8: 长债利率-广发中债7-10年国开债指数A（003376.OF）
F9: 长债信用-易方达优选投资级信用指数发起式A（018996.OF）
F10: 中短债-嘉实中短债债券A（006797.OF）
F11: 投顾组合-嘉蝠固收优选
B12: 波动生息 | C12: 投顾组合（e.g.梧桐） | D12: LC+4% | E12: 策略稳定、业绩可追溯 | F12: 梧桐系列
B13: 低波多资产 | C13: 投顾组合（e.g.百灵） | D13: 中证MARP （930929.CSI） | E13: 策略稳定、业绩可追溯 | F13: 百灵
A14: 保障 | B14: 黄金 | C14: 指数基金 | D14: 上海金 | E14: 1.规模、流动性 | F14: 国泰黄金ETF联接A（000218.OF） 华安黄金ETF联接A（000216.OF）

Sheet 增值序列
B1: 50%奇点1号+50%奇点2号 | G1: 931187.CSI | H1: 300-500-1000-2000指增等权
A2: 日期 | B2: 奇点组合 | C2: 奇点1号 | D2: 奇点2号 | E2: 科创创业50等权 | F2: 中证800 | G2: 中证科技100 | H2: 指增组合 | I2: 增值组合
A3: 43832 | B3: 1.0255811 | C3: 1.0238067 | D3: 1.0273555 | E3: 1.022877 | F3: 1.0147986 | G3: =[1]!thsiFinD("ths_int_chg_ratio_index",G$1,$A$3,$A3,101)/100+1 -> 1.0262842 | H3: 1.0173101 | I3: =D3*0.5+H3*0.5 -> 1.0223328 | J3: =I3/I2-1 -> #VALUE! | K3: =MAX(I$3:I3) -> 1.0223328 | L3: =I3/K3-1 -> 0
A4: 43833 | B4: 1.0299986 | C4: 1.0262594 | D4: 1.0337378 | E4: 1.0237908 | F4: 1.0140972 | G4: =[1]!thsiFinD("ths_int_chg_ratio_index",G$1,$A$3,$A4,101)/100+1 -> 1.0279941 | H4: 1.0202139 | I4: =D4*0.5+H4*0.5 -> 1.0269759 | J4: =I4/I3-1 -> 0.0045416487 | K4: =MAX(I$3:I4) -> 1.0269759 | L4: =I4/K4-1 -> 0
A5: 43836 | B5: 1.0380842 | C5: 1.0318116 | D5: 1.0443567 | E5: 1.0321693 | F5: 1.0136224 | G5: =[1]!thsiFinD("ths_int_chg_ratio_index",G$1,$A$3,$A5,101)/100+1 -> 1.028522 | H5: 1.0263972 | I5: =D5*0.5+H5*0.5 -> 1.0353769 | J5: =I5/I4-1 -> 0.0081804002 | K5: =MAX(I$3:I5) -> 1.0353769 | L5: =I5/K5-1 -> 0
A6: 43837 | B6: 1.0444645 | C6: 1.0400458 | D6: 1.0488831 | E6: 1.0429945 | F6: 1.0223099 | G6: =[1]!thsiFinD("ths_int_chg_ratio_index",G$1,$A$3,$A6,101)/100+1 -> 1.0379423 | H6: 1.0393231 | I6: =D6*0.5+H6*0.5 -> 1.0441031 | J6: =I6/I5-1 -> 0.0084280108 | K6: =MAX(I$3:I6) -> 1.0441031 | L6: =I6/K6-1 -> 0
A7: 43838 | B7: 1.0299565 | C7: 1.0269667 | D7: 1.0329462 | E7: 1.0372105 | F7: 1.0099639 | G7: =[1]!thsiFinD("ths_int_chg_ratio_index",G$1,$A$3,$A7,101)/100+1 -> 1.029766 | H7: 1.0261808 | I7: =D7*0.5+H7*0.5 -> 1.0295635 | J7: =I7/I6-1 -> -0.013925434 | K7: =MAX(I$3:I7) -> 1.0441031 | L7: =I7/K7-1 -> -0.013925434
A8: 43839 | B8: 1.0578962 | C8: 1.0559455 | D8: 1.0598469 | E8: 1.0643465 | F8: 1.0229774 | G8: =[1]!thsiFinD("ths_int_chg_ratio_index",G$1,$A$3,$A8,101)/100+1 -> 1.0521272 | H8: 1.0416767 | I8: =D8*0.5+H8*0.5 -> 1.0507618 | J8: =I8/I7-1 -> 0.020589586 | K8: =MAX(I$3:I8) -> 1.0507618 | L8: =I8/K8-1 -> 0
A9: 43840 | B9: 1.0629979 | C9: 1.0585585 | D9: 1.0674373 | E9: 1.0626663 | F9: 1.0219762 | G9: =[1]!thsiFinD("ths_int_chg_ratio_index",G$1,$A$3,$A9,101)/100+1 -> 1.055762 | H9: 1.0406964 | I9: =D9*0.5+H9*0.5 -> 1.0540669 | J9: =I9/I8-1 -> 0.0031454061 | K9: =MAX(I$3:I9) -> 1.0540669 | L9: =I9/K9-1 -> 0
A10: 43843 | B10: 1.093894 | C10: 1.0909374 | D10: 1.0968505 | E10: 1.092189 | F10: 1.0331502 | G10: =[1]!thsiFinD("ths_int_chg_ratio_index",G$1,$A$3,$A10,101)/100+1 -> 1.0708176 | H10: 1.0533907 | I10: =D10*0.5+H10*0.5 -> 1.0751206 | J10: =I10/I9-1 -> 0.019973835 | K10: =MAX(I$3:I10) -> 1.0751206 | L10: =I10/K10-1 -> 0
A11: 43844 | B11: 1.0917522 | C11: 1.0894067 | D11: 1.0940977 | E11: 1.0935226 | F11: 1.0297456 | G11: =[1]!thsiFinD("ths_int_chg_ratio_index",G$1,$A$3,$A11,101)/100+1 -> 1.0645131 | H11: 1.0518627 | I11: =D11*0.5+H11*0.5 -> 1.0729802 | J11: =I11/I10-1 -> -0.0019908755 | K11: =MAX(I$3:I11) -> 1.0751206 | L11: =I11/K11-1 -> -0.0019908755
A12: 43845 | B12: 1.0981376 | C12: 1.096209 | D12: 1.1000663 | E12: 1.0960574 | F12: 1.0248815 | G12: =[1]!thsiFinD("ths_int_chg_ratio_index",G$1,$A$3,$A12,101)/100+1 -> 1.0682675 | H12: 1.0491022 | I12: =D12*0.5+H12*0.5 -> 1.0745843 | J12: =I12/I11-1 -> 0.0014949614 | K12: =MAX(I$3:I12) -> 1.0751206 | L12: =I12/K12-1 -> -0.00049889037
A13: 43846 | B13: 1.1074447 | C13: 1.1110572 | D13: 1.1038321 | E13: 1.1141374 | F13: 1.0214824 | G13: =[1]!thsiFinD("ths_int_chg_ratio_index",G$1,$A$3,$A13,101)/100+1 -> 1.0674689 | H13: 1.0476066 | I13: =D13*0.5+H13*0.5 -> 1.0757194 | J13: =I13/I12-1 -> 0.0010563363 | K13: =MAX(I$3:I13) -> 1.0757194 | L13: =I13/K13-1 -> 0
A14: 43847 | B14: 1.119527 | C14: 1.1336678 | D14: 1.1053862 | E14: 1.151934 | F14: 1.0217692 | G14: =[1]!thsiFinD("ths_int_chg_ratio_index",G$1,$A$3,$A14,101)/100+1 -> 1.0708384 | H14: 1.0448327 | I14: =D14*0.5+H14*0.5 -> 1.0751094 | J14: =I14/I13-1 -> -0.00056702124 | K14: =MAX(I$3:I14) -> 1.0757194 | L14: =I14/K14-1 -> -0.00056702124
... A1534: 46142 | B1534: 3.8381333 | C1534: 2.6500447 | D1534: 5.0262218 | E1534: 1.5769944 | F1534: 1.2658054 | G1534: =[1]!thsiFinD("ths_int_chg_ratio_index",G$1,$A$3,$A1534,101)/100+1 -> 2.0603068 | H1534: 2.0825817 | I1534: =D1534*0.5+H1534*0.5 -> 3.5544017 | J1534: =I1534/I1533-1 -> 0.0024991528 | K1534: =MAX(I$3:I1534) -> 3.6092552 | L1534: =I1534/K1534-1 -> -0.015198002
J1536: =STDEV(J4:J1534)*250^0.5 -> 0.24782811 | L1536: =MIN(L3:L1534) -> -0.39015008
H1537: 43830 | I1537: 1
H1538: 44195 | I1538: =VLOOKUP($H1538,$A$3:$L$1534,9,0) -> 1.4335467 | J1538: =I1538/I1537-1 -> 0.43354675
H1539: 44561 | I1539: =VLOOKUP($H1539,$A$3:$L$1534,9,0) -> 1.7865133 | J1539: =I1539/I1538-1 -> 0.24621908
H1540: 44925 | I1540: =VLOOKUP($H1540,$A$3:$L$1534,9,0) -> 1.3999675 | J1540: =I1540/I1539-1 -> -0.21636882
H1541: 45289 | I1541: =VLOOKUP($H1541,$A$3:$L$1534,9,0) -> 1.3931329 | J1541: =I1541/I1540-1 -> -0.0048819712
H1542: 45657 | I1542: =VLOOKUP($H1542,$A$3:$L$1534,9,0) -> 1.6760462 | J1542: =I1542/I1541-1 -> 0.20307703
H1543: 46022 | I1543: =VLOOKUP($H1543,$A$3:$L$1534,9,0) -> 2.871303 | J1543: =I1543/I1542-1 -> 0.71314067
H1544: 46142 | I1544: =VLOOKUP($H1544,$A$3:$L$1534,9,0) -> 3.5544017 | J1544: =I1544/I1543-1 -> 0.23790549
J1545: =I1544-1 -> 2.5544017

Sheet 增值

Sheet 增值-产业趋势
A1: 代码 | B1: 931160.CSI | C1: 931743.CSI | D1: 000688.SH | E1: 399673.SZ | F1: 000940.OF | G1: 001513.OF | H1: 001480.OF | I1: 001323.OF | M1: 932381.CSI | N1: 000906.SH | O1: 15 | P1: 16 | Q1: 17 | R1: 18 | S1: 19
A2: =[1]!HX_AutoDate(1,"2020-01-1","2026-09-18",-1,-1,0,0,0,0,0,"SSE",1629,0) -> 日期 | B2: 中证全指通信设备 | C2: 中证半导体材料设备 | D2: 科创50 | E2: 创业板50 | F2: 富国曹晋 | G2: 易方达郑希 | H2: 财通金梓才 | I2: 东吴刘元海 | J2: 奇点组合 | K2: 奇点1号 | L2: 奇点2号 | M2: 科创创业50等权 | N2: 中证800 | O2: 奇点组合 | P2: 奇点1号 | Q2: 奇点2号 | R2: 科创创业50等权 | S2: 中证800
A3: 43832 | B3: 0.25 | C3: 0.25 | D3: 0.25 | E3: 0.25 | F3: 0.25 | G3: 0.25 | H3: 0.25 | I3: 0.25 | J3: 50%奇点1号+50%奇点2号 | K3: =SUMPRODUCT(B3:E3,B$3:E$3)/100 -> 0.0025 | L3: =SUMPRODUCT(F3:I3,F$3:I$3)/100 -> 0.0025 | O3: 50%奇点1号+50%奇点2号 | Q3: =L3+1 -> 1.0025 | R3: =M3+1 -> 1
A4: 43833 | B4: =[1]!thsiFinD("ths_int_chg_ratio_index",B$1,$A$4,$A4,101) -> 0.50890893 | C4: =[1]!thsiFinD("ths_int_chg_ratio_index",C$1,$A$4,$A4,101) -> -0.092007055 | D4: =[1]!thsiFinD("ths_int_chg_ratio_index",D$1,$A$4,$A4,101) -> 0.46664615 | E4: =[1]!thsiFinD("ths_int_chg_ratio_index",E$1,$A$4,$A4,101) -> 0.080616317 | F4: =[1]!thsiFinD("ths_adjustment_nvg_ratio_fund",F$1,$A$4,$A4,101) -> 0.6752609 | G4: =[1]!thsiFinD("ths_adjustment_nvg_ratio_fund",G$1,$A$4,$A4,101) -> 0.5107832 | H4: =[1]!thsiFinD("ths_adjustment_nvg_ratio_fund",H$1,$A$4,$A4,101) -> 1 | I4: =[1]!thsiFinD("ths_adjustment_nvg_ratio_fund",I$1,$A$4,$A4,101) -> 0.29296875 | J4: =50%*K4+50%*L4 -> 0.0043039715 | K4: =SUMPRODUCT(B4:E4,B$3:E$3)/100 -> 0.0024104109 | L4: =SUMPRODUCT(F4:I4,F$3:I$3)/100 -> 0.0061975321 | M4: =[1]!thsiFinD("ths_int_chg_ratio_index",M$1,$A$4,$A4,101)/100 -> 0.00089336255 | N4: =[1]!thsiFinD("ths_int_chg_ratio_index",N$1,$A$4,$A4,101)/100 -> -0.00069124917 | O4: =J4+1 -> 1.004304 | P4: =K4+1 -> 1.0024104 | Q4: =L4+1 -> 1.0061975 | R4: =M4+1 -> 1.0008934 | S4: =N4+1 -> 0.99930875
A5: 43836 | B5: =[1]!thsiFinD("ths_int_chg_ratio_index",B$1,$A$4,$A5,101) -> 1.196003 | C5: =[1]!thsiFinD("ths_int_chg_ratio_index",C$1,$A$4,$A5,101) -> 0.094581477 | D5: =[1]!thsiFinD("ths_int_chg_ratio_index",D$1,$A$4,$A5,101) -> 0.74077931 | E5: =[1]!thsiFinD("ths_int_chg_ratio_index",E$1,$A$4,$A5,101) -> 1.1102243 | F5: =[1]!thsiFinD("ths_adjustment_nvg_ratio_fund",F$1,$A$4,$A5,101) -> 1.2891344 | G5: =[1]!thsiFinD("ths_adjustment_nvg_ratio_fund",G$1,$A$4,$A5,101) -> 2.4971623 | H5: =[1]!thsiFinD("ths_adjustment_nvg_ratio_fund",H$1,$A$4,$A5,101) -> 1.8461538 | I5: =[1]!thsiFinD("ths_adjustment_nvg_ratio_fund",I$1,$A$4,$A5,101) -> 0.9765625 | J5: =50%*K5+50%*L5 -> 0.012188251 | K5: =SUMPRODUCT(B5:E5,B$3:E$3)/100 -> 0.0078539702 | L5: =SUMPRODUCT(F5:I5,F$3:I$3)/100 -> 0.016522533 | M5: =[1]!thsiFinD("ths_int_chg_ratio_index",M$1,$A$4,$A5,101)/100 -> 0.0090844745 | N5: =[1]!thsiFinD("ths_int_chg_ratio_index",N$1,$A$4,$A5,101)/100 -> -0.0011590682 | O5: =J5+1 -> 1.0121883 | P5: =K5+1 -> 1.007854 | Q5: =L5+1 -> 1.0165225 | R5: =M5+1 -> 1.0090845 | S5: =N5+1 -> 0.99884093 | T5: =O5/O4-1 -> 0.0078504917 | U5: =P5/P4-1 -> 0.0054304697 | V5: =Q5/Q4-1 -> 0.010261405 | W5: =R5/R4-1 -> 0.0081838008 | X5: =S5/S4-1 -> -0.00046814265 | Y5: =MAX(O$4:O5) -> 1.0121883 | Z5: =MAX(P$4:P5) -> 1.007854 | AA5: =MAX(Q$4:Q5) -> 1.0165225 | AB5: =MAX(R$4:R5) -> 1.0090845 | AC5: =MAX(S$4:S5) -> 0.99930875 | AD5: =O5/Y5-1 -> 0 | AE5: =P5/Z5-1 -> 0 | AF5: =Q5/AA5-1 -> 0 | AG5: =R5/AB5-1 -> 0 | AH5: =S5/AC5-1 -> -0.00046814265
A6: 43837 | B6: =[1]!thsiFinD("ths_int_chg_ratio_index",B$1,$A$4,$A6,101) -> 1.7819438 | C6: =[1]!thsiFinD("ths_int_chg_ratio_index",C$1,$A$4,$A6,101) -> 0.076288139 | D6: =[1]!thsiFinD("ths_int_chg_ratio_index",D$1,$A$4,$A6,101) -> 2.2908075 | E6: =[1]!thsiFinD("ths_int_chg_ratio_index",E$1,$A$4,$A6,101) -> 2.2261475 | F6: =[1]!thsiFinD("ths_adjustment_nvg_ratio_fund",F$1,$A$4,$A6,101) -> 1.7188459 | G6: =[1]!thsiFinD("ths_adjustment_nvg_ratio_fund",G$1,$A$4,$A6,101) -> 2.6674234 | H6: =[1]!thsiFinD("ths_adjustment_nvg_ratio_fund",H$1,$A$4,$A6,101) -> 2.2307692 | I6: =[1]!thsiFinD("ths_adjustment_nvg_ratio_fund",I$1,$A$4,$A6,101) -> 1.7578125 | J6: =50%*K6+50%*L6 -> 0.018437547 | K6: =SUMPRODUCT(B6:E6,B$3:E$3)/100 -> 0.015937967 | L6: =SUMPRODUCT(F6:I6,F$3:I$3)/100 -> 0.020937128 | M6: =[1]!thsiFinD("ths_int_chg_ratio_index",M$1,$A$4,$A6,101)/100 -> 0.019667565 | N6: =[1]!thsiFinD("ths_int_chg_ratio_index",N$1,$A$4,$A6,101)/100 -> 0.0074017532 | O6: =J6+1 -> 1.0184375 | P6: =K6+1 -> 1.015938 | Q6: =L6+1 -> 1.0209371 | R6: =M6+1 -> 1.0196676 | S6: =N6+1 -> 1.0074018 | T6: =O6/O5-1 -> 0.0061740451 | U6: =P6/P5-1 -> 0.0080210004 | V6: =Q6/Q5-1 -> 0.0043428401 | W6: =R6/R5-1 -> 0.010487814 | X6: =S6/S5-1 -> 0.0085707555 | Y6: =MAX(O$4:O6) -> 1.0184375 | Z6: =MAX(P$4:P6) -> 1.015938 | AA6: =MAX(Q$4:Q6) -> 1.0209371 | AB6: =MAX(R$4:R6) -> 1.0196676 | AC6: =MAX(S$4:S6) -> 1.0074018 | AD6: =O6/Y6-1 -> 0 | AE6: =P6/Z6-1 -> 0 | AF6: =Q6/AA6-1 -> 0 | AG6: =R6/AB6-1 -> 0 | AH6: =S6/AC6-1 -> 0
A7: 43838 | B7: =[1]!thsiFinD("ths_int_chg_ratio_index",B$1,$A$4,$A7,101) -> -0.31280878 | C7: =[1]!thsiFinD("ths_int_chg_ratio_index",C$1,$A$4,$A7,101) -> -2.221551 | D7: =[1]!thsiFinD("ths_int_chg_ratio_index",D$1,$A$4,$A7,101) -> 3.0828458 | E7: =[1]!thsiFinD("ths_int_chg_ratio_index",E$1,$A$4,$A7,101) -> 0.73537017 | F7: =[1]!thsiFinD("ths_adjustment_nvg_ratio_fund",F$1,$A$4,$A7,101) -> 0.85942296 | G7: =[1]!thsiFinD("ths_adjustment_nvg_ratio_fund",G$1,$A$4,$A7,101) -> 1.4755959 | H7: =[1]!thsiFinD("ths_adjustment_nvg_ratio_fund",H$1,$A$4,$A7,101) -> -0.53846154 | I7: =[1]!thsiFinD("ths_adjustment_nvg_ratio_fund",I$1,$A$4,$A7,101) -> 0.390625 | J7: =50%*K7+50%*L7 -> 0.0043387981 | K7: =SUMPRODUCT(B7:E7,B$3:E$3)/100 -> 0.0032096404 | L7: =SUMPRODUCT(F7:I7,F$3:I$3)/100 -> 0.0054679558 | M7: =[1]!thsiFinD("ths_int_chg_ratio_index",M$1,$A$4,$A7,101)/100 -> 0.014012926 | N7: =[1]!thsiFinD("ths_int_chg_ratio_index",N$1,$A$4,$A7,101)/100 -> -0.0047642137 | O7: =J7+1 -> 1.0043388 | P7: =K7+1 -> 1.0032096 | Q7: =L7+1 -> 1.005468 | R7: =M7+1 -> 1.0140129 | S7: =N7+1 -> 0.99523579 | T7: =O7/O6-1 -> -0.013843509 | U7: =P7/P6-1 -> -0.012528646 | V7: =Q7/Q6-1 -> -0.015151934 | W7: =R7/R6-1 -> -0.0055455709 | X7: =S7/S6-1 -> -0.012076579 | Y7: =MAX(O$4:O7) -> 1.0184375 | Z7: =MAX(P$4:P7) -> 1.015938 | AA7: =MAX(Q$4:Q7) -> 1.0209371 | AB7: =MAX(R$4:R7) -> 1.0196676 | AC7: =MAX(S$4:S7) -> 1.0074018 | AD7: =O7/Y7-1 -> -0.013843509 | AE7: =P7/Z7-1 -> -0.012528646 | AF7: =Q7/AA7-1 -> -0.015151934 | AG7: =R7/AB7-1 -> -0.0055455709 | AH7: =S7/AC7-1 -> -0.012076579
A8: 43839 | B8: =[1]!thsiFinD("ths_int_chg_ratio_index",B$1,$A$4,$A8,101) -> 2.9441021 | C8: =[1]!thsiFinD("ths_int_chg_ratio_index",C$1,$A$4,$A8,101) -> 0.12210496 | D8: =[1]!thsiFinD("ths_int_chg_ratio_index",D$1,$A$4,$A8,101) -> 5.745509 | E8: =[1]!thsiFinD("ths_int_chg_ratio_index",E$1,$A$4,$A8,101) -> 3.8041247 | F8: =[1]!thsiFinD("ths_adjustment_nvg_ratio_fund",F$1,$A$4,$A8,101) -> 3.4376918 | G8: =[1]!thsiFinD("ths_adjustment_nvg_ratio_fund",G$1,$A$4,$A8,101) -> 3.6322361 | H8: =[1]!thsiFinD("ths_adjustment_nvg_ratio_fund",H$1,$A$4,$A8,101) -> 3.2307692 | I8: =[1]!thsiFinD("ths_adjustment_nvg_ratio_fund",I$1,$A$4,$A8,101) -> 2.34375 | J8: =50%*K8+50%*L8 -> 0.03157536 | K8: =SUMPRODUCT(B8:E8,B$3:E$3)/100 -> 0.031539602 | L8: =SUMPRODUCT(F8:I8,F$3:I$3)/100 -> 0.031611118 | M8: =[1]!thsiFinD("ths_int_chg_ratio_index",M$1,$A$4,$A8,101)/100 -> 0.04054202 | N8: =[1]!thsiFinD("ths_int_chg_ratio_index",N$1,$A$4,$A8,101)/100 -> 0.0080594913 | O8: =J8+1 -> 1.0315754 | P8: =K8+1 -> 1.0315396 | Q8: =L8+1 -> 1.0316111 | R8: =M8+1 -> 1.040542 | S8: =N8+1 -> 1.0080595 | T8: =O8/O7-1 -> 0.027118898 | U8: =P8/P7-1 -> 0.028239324 | V8: =Q8/Q7-1 -> 0.02600099 | W8: =R8/R7-1 -> 0.026162481 | X8: =S8/S7-1 -> 0.012885092 | Y8: =MAX(O$4:O8) -> 1.0315754 | Z8: =MAX(P$4:P8) -> 1.0315396 | AA8: =MAX(Q$4:Q8) -> 1.0316111 | AB8: =MAX(R$4:R8) -> 1.040542 | AC8: =MAX(S$4:S8) -> 1.0080595 | AD8: =O8/Y8-1 -> 0 | AE8: =P8/Z8-1 -> 0 | AF8: =Q8/AA8-1 -> 0 | AG8: =R8/AB8-1 -> 0 | AH8: =S8/AC8-1 -> 0
A9: 43840 | B9: =[1]!thsiFinD("ths_int_chg_ratio_index",B$1,$A$4,$A9,101) -> 3.1634807 | C9: =[1]!thsiFinD("ths_int_chg_ratio_index",C$1,$A$4,$A9,101) -> 1.417167 | D9: =[1]!thsiFinD("ths_int_chg_ratio_index",D$1,$A$4,$A9,101) -> 5.5617533 | E9: =[1]!thsiFinD("ths_int_chg_ratio_index",E$1,$A$4,$A9,101) -> 3.472864 | F9: =[1]!thsiFinD("ths_adjustment_nvg_ratio_fund",F$1,$A$4,$A9,101) -> 3.7446286 | G9: =[1]!thsiFinD("ths_adjustment_nvg_ratio_fund",G$1,$A$4,$A9,101) -> 4.0862656 | H9: =[1]!thsiFinD("ths_adjustment_nvg_ratio_fund",H$1,$A$4,$A9,101) -> 4.9230769 | I9: =[1]!thsiFinD("ths_adjustment_nvg_ratio_fund",I$1,$A$4,$A9,101) -> 2.8320312 | J9: =50%*K9+50%*L9 -> 0.036501584 | K9: =SUMPRODUCT(B9:E9,B$3:E$3)/100 -> 0.034038162 | L9: =SUMPRODUCT(F9:I9,F$3:I$3)/100 -> 0.038965006 | M9: =[1]!thsiFinD("ths_int_chg_ratio_index",M$1,$A$4,$A9,101)/100 -> 0.038899398 | N9: =[1]!thsiFinD("ths_int_chg_ratio_index",N$1,$A$4,$A9,101)/100 -> 0.0070728611 | O9: =J9+1 -> 1.0365016 | P9: =K9+1 -> 1.0340382 | Q9: =L9+1 -> 1.038965 | R9: =M9+1 -> 1.0388994 | S9: =N9+1 -> 1.0070729 | T9: =O9/O8-1 -> 0.0047754381 | U9: =P9/P8-1 -> 0.0024221663 | V9: =Q9/Q8-1 -> 0.0071285467 | W9: =R9/R8-1 -> -0.0015786212 | X9: =S9/S8-1 -> -0.00097874203 | Y9: =MAX(O$4:O9) -> 1.0365016 | Z9: =MAX(P$4:P9) -> 1.0340382 | AA9: =MAX(Q$4:Q9) -> 1.038965 | AB9: =MAX(R$4:R9) -> 1.040542 | AC9: =MAX(S$4:S9) -> 1.0080595 | AD9: =O9/Y9-1 -> 0 | AE9: =P9/Z9-1 -> 0 | AF9: =Q9/AA9-1 -> 0 | AG9: =R9/AB9-1 -> -0.0015786212 | AH9: =S9/AC9-1 -> -0.00097874203 | AT9: 2020/1/1-2026/4/30 | AU9: 奇点组合 | AV9: 奇点1号（指数） | AW9: 奇点2号（主动） | AX9: 科创创业50等权指数 | AY9: 中证800 | AZ9: 指增
A10: 43843 | B10: =[1]!thsiFinD("ths_int_chg_ratio_index",B$1,$A$4,$A10,101) -> 5.4744392 | C10: =[1]!thsiFinD("ths_int_chg_ratio_index",C$1,$A$4,$A10,101) -> 7.1878804 | D10: =[1]!thsiFinD("ths_int_chg_ratio_index",D$1,$A$4,$A10,101) -> 8.4458884 | E10: =[1]!thsiFinD("ths_int_chg_ratio_index",E$1,$A$4,$A10,101) -> 5.1033537 | F10: =[1]!thsiFinD("ths_adjustment_nvg_ratio_fund",F$1,$A$4,$A10,101) -> 6.3842848 | G10: =[1]!thsiFinD("ths_adjustment_nvg_ratio_fund",G$1,$A$4,$A10,101) -> 6.8671964 | H10: =[1]!thsiFinD("ths_adjustment_nvg_ratio_fund",H$1,$A$4,$A10,101) -> 9.0769231 | I10: =[1]!thsiFinD("ths_adjustment_nvg_ratio_fund",I$1,$A$4,$A10,101) -> 4.6875 | J10: =50%*K10+50%*L10 -> 0.066534332 | K10: =SUMPRODUCT(B10:E10,B$3:E$3)/100 -> 0.065528904 | L10: =SUMPRODUCT(F10:I10,F$3:I$3)/100 -> 0.067539761 | M10: =[1]!thsiFinD("ths_int_chg_ratio_index",M$1,$A$4,$A10,101)/100 -> 0.067761813 | N10: =[1]!thsiFinD("ths_int_chg_ratio_index",N$1,$A$4,$A10,101)/100 -> 0.018083906 | O10: =J10+1 -> 1.0665343 | P10: =K10+1 -> 1.0655289 | Q10: =L10+1 -> 1.0675398 | R10: =M10+1 -> 1.0677618 | S10: =N10+1 -> 1.0180839 | T10: =O10/O9-1 -> 0.028975111 | U10: =P10/P9-1 -> 0.030454139 | V10: =Q10/Q9-1 -> 0.027503096 | W10: =R10/R9-1 -> 0.027781722 | X10: =S10/S9-1 -> 0.010933712 | Y10: =MAX(O$4:O10) -> 1.0665343 | Z10: =MAX(P$4:P10) -> 1.0655289 | AA10: =MAX(Q$4:Q10) -> 1.0675398 | AB10: =MAX(R$4:R10) -> 1.0677618 | AC10: =MAX(S$4:S10) -> 1.0180839 | AD10: =O10/Y10-1 -> 0 | AE10: =P10/Z10-1 -> 0 | AF10: =Q10/AA10-1 -> 0 | AG10: =R10/AB10-1 -> 0 | AH10: =S10/AC10-1 -> 0 | AT10: 累计收益率 | AU10: =J1535 -> 2.8269589 | AV10: =K1552 -> 2.0271764 | AW10: =L1552 -> 4.8380314 | AX10: =M1552 -> 0.74842107 | AY10: =N1552 -> 0.26348381 | AZ10: ='增值-指数增强'!AE7 -> 1.0825817 | BA10: =增值序列!J1545 -> 2.5544017
A11: 43844 | B11: =[1]!thsiFinD("ths_int_chg_ratio_index",B$1,$A$4,$A11,101) -> 4.0253222 | C11: =[1]!thsiFinD("ths_int_chg_ratio_index",C$1,$A$4,$A11,101) -> 7.3459877 | D11: =[1]!thsiFinD("ths_int_chg_ratio_index",D$1,$A$4,$A11,101) -> 9.6676118 | E11: =[1]!thsiFinD("ths_int_chg_ratio_index",E$1,$A$4,$A11,101) -> 4.5674686 | F11: =[1]!thsiFinD("ths_adjustment_nvg_ratio_fund",F$1,$A$4,$A11,101) -> 6.0773481 | G11: =[1]!thsiFinD("ths_adjustment_nvg_ratio_fund",G$1,$A$4,$A11,101) -> 7.2077185 | H11: =[1]!thsiFinD("ths_adjustment_nvg_ratio_fund",H$1,$A$4,$A11,101) -> 8.0769231 | I11: =[1]!thsiFinD("ths_adjustment_nvg_ratio_fund",I$1,$A$4,$A11,101) -> 4.5898438 | J11: =50%*K11+50%*L11 -> 0.06444778 | K11: =SUMPRODUCT(B11:E11,B$3:E$3)/100 -> 0.064015976 | L11: =SUMPRODUCT(F11:I11,F$3:I$3)/100 -> 0.064879583 | M11: =[1]!thsiFinD("ths_int_chg_ratio_index",M$1,$A$4,$A11,101)/100 -> 0.069065587 | N11: =[1]!thsiFinD("ths_int_chg_ratio_index",N$1,$A$4,$A11,101)/100 -> 0.014728953 | O11: =J11+1 -> 1.0644478 | P11: =K11+1 -> 1.064016 | Q11: =L11+1 -> 1.0648796 | R11: =M11+1 -> 1.0690656 | S11: =N11+1 -> 1.014729 | T11: =O11/O10-1 -> -0.0019563859 | U11: =P11/P10-1 -> -0.0014198848 | V11: =Q11/Q10-1 -> -0.0024918765 | W11: =R11/R10-1 -> 0.0012210341 | X11: =S11/S10-1 -> -0.0032953596 | Y11: =MAX(O$4:O11) -> 1.0665343 | Z11: =MAX(P$4:P11) -> 1.0655289 | AA11: =MAX(Q$4:Q11) -> 1.0675398 | AB11: =MAX(R$4:R11) -> 1.0690656 | AC11: =MAX(S$4:S11) -> 1.0180839 | AD11: =O11/Y11-1 -> -0.0019563859 | AE11: =P11/Z11-1 -> -0.0014198848 | AF11: =Q11/AA11-1 -> -0.0024918765 | AG11: =R11/AB11-1 -> 0 | AH11: =S11/AC11-1 -> -0.0032953596 | AT11: 最大回撤 | AU11: =MIN(AD5:AD1535) -> -0.45012326 | AV11: =MIN(AE5:AE1535) -> -0.54459836 | AW11: =MIN(AF5:AF1535) -> -0.39614942 | AX11: =MIN(AG5:AG1535) -> -0.62688287 | AY11: =MIN(AH5:AH1535) -> -0.42957366 | AZ11: ='增值-指数增强'!AE8 -> -0.39461055 | BA11: =增值序列!L1536 -> -0.39015008
A12: 43845 | B12: =[1]!thsiFinD("ths_int_chg_ratio_index",B$1,$A$4,$A12,101) -> 4.4349226 | C12: =[1]!thsiFinD("ths_int_chg_ratio_index",C$1,$A$4,$A12,101) -> 9.8769044 | D12: =[1]!thsiFinD("ths_int_chg_ratio_index",D$1,$A$4,$A12,101) -> 9.3203804 | E12: =[1]!thsiFinD("ths_int_chg_ratio_index",E$1,$A$4,$A12,101) -> 4.59446 | F12: =[1]!thsiFinD("ths_adjustment_nvg_ratio_fund",F$1,$A$4,$A12,101) -> 7.3050952 | G12: =[1]!thsiFinD("ths_adjustment_nvg_ratio_fund",G$1,$A$4,$A12,101) -> 7.3779796 | H12: =[1]!thsiFinD("ths_adjustment_nvg_ratio_fund",H$1,$A$4,$A12,101) -> 8.6153846 | I12: =[1]!thsiFinD("ths_adjustment_nvg_ratio_fund",I$1,$A$4,$A12,101) -> 4.9804688 | J12: =50%*K12+50%*L12 -> 0.070631994 | K12: =SUMPRODUCT(B12:E12,B$3:E$3)/100 -> 0.070566668 | L12: =SUMPRODUCT(F12:I12,F$3:I$3)/100 -> 0.07069732 | M12: =[1]!thsiFinD("ths_int_chg_ratio_index",M$1,$A$4,$A12,101)/100 -> 0.071543695 | N12: =[1]!thsiFinD("ths_int_chg_ratio_index",N$1,$A$4,$A12,101)/100 -> 0.0099358575 | O12: =J12+1 -> 1.070632 | P12: =K12+1 -> 1.0705667 | Q12: =L12+1 -> 1.0706973 | R12: =M12+1 -> 1.0715437 | S12: =N12+1 -> 1.0099359 | T12: =O12/O11-1 -> 0.0058097868 | U12: =P12/P11-1 -> 0.0061565735 | V12: =Q12/Q11-1 -> 0.0054632813 | W12: =R12/R11-1 -> 0.0023180134 | X12: =S12/S11-1 -> -0.0047235229 | Y12: =MAX(O$4:O12) -> 1.070632 | Z12: =MAX(P$4:P12) -> 1.0705667 | AA12: =MAX(Q$4:Q12) -> 1.0706973 | AB12: =MAX(R$4:R12) -> 1.0715437 | AC12: =MAX(S$4:S12) -> 1.0180839 | AD12: =O12/Y12-1 -> 0 | AE12: =P12/Z12-1 -> 0 | AF12: =Q12/AA12-1 -> 0 | AG12: =R12/AB12-1 -> 0 | AH12: =S12/AC12-1 -> -0.0080033168 | AN12: 43830 | AO12: 1 | AP12: 1 | AQ12: 1 | AR12: 1 | AS12: 1 | AT12: 年化波动率 | AU12: =STDEV(T5:T1535)*250^0.5 -> 0.29534112 | AV12: =STDEV(U5:U1535)*250^0.5 -> 0.31017148 | AW12: =STDEV(V5:V1535)*250^0.5 -> 0.29742333 | AX12: =STDEV(W5:W1535)*250^0.5 -> 0.29226288 | AY12: =STDEV(X5:X1535)*250^0.5 -> 0.18947229 | AZ12: ='增值-指数增强'!AE9 -> 0.20526196 | BA12: =增值序列!J1536 -> 0.24782811
A13: 43846 | B13: =[1]!thsiFinD("ths_int_chg_ratio_index",B$1,$A$4,$A13,101) -> 4.1806114 | C13: =[1]!thsiFinD("ths_int_chg_ratio_index",C$1,$A$4,$A13,101) -> 11.73663 | D13: =[1]!thsiFinD("ths_int_chg_ratio_index",D$1,$A$4,$A13,101) -> 13.197638 | E13: =[1]!thsiFinD("ths_int_chg_ratio_index",E$1,$A$4,$A13,101) -> 4.9016698 | F13: =[1]!thsiFinD("ths_adjustment_nvg_ratio_fund",F$1,$A$4,$A13,101) -> 8.7170043 | G13: =[1]!thsiFinD("ths_adjustment_nvg_ratio_fund",G$1,$A$4,$A13,101) -> 7.2077185 | H13: =[1]!thsiFinD("ths_adjustment_nvg_ratio_fund",H$1,$A$4,$A13,101) -> 8.4615385 | I13: =[1]!thsiFinD("ths_adjustment_nvg_ratio_fund",I$1,$A$4,$A13,101) -> 5.3710938 | J13: =50%*K13+50%*L13 -> 0.07971738 | K13: =SUMPRODUCT(B13:E13,B$3:E$3)/100 -> 0.085041373 | L13: =SUMPRODUCT(F13:I13,F$3:I$3)/100 -> 0.074393388 | M13: =[1]!thsiFinD("ths_int_chg_ratio_index",M$1,$A$4,$A13,101)/100 -> 0.089219329 | N13: =[1]!thsiFinD("ths_int_chg_ratio_index",N$1,$A$4,$A13,101)/100 -> 0.0065862713 | O13: =J13+1 -> 1.0797174 | P13: =K13+1 -> 1.0850414 | Q13: =L13+1 -> 1.0743934 | R13: =M13+1 -> 1.0892193 | S13: =N13+1 -> 1.0065863 | T13: =O13/O12-1 -> 0.0084860028 | U13: =P13/P12-1 -> 0.013520601 | V13: =Q13/Q12-1 -> 0.0034520188 | W13: =R13/R12-1 -> 0.016495486 | X13: =S13/S12-1 -> -0.0033166326 | Y13: =MAX(O$4:O13) -> 1.0797174 | Z13: =MAX(P$4:P13) -> 1.0850414 | AA13: =MAX(Q$4:Q13) -> 1.0743934 | AB13: =MAX(R$4:R13) -> 1.0892193 | AC13: =MAX(S$4:S13) -> 1.0180839 | AD13: =O13/Y13-1 -> 0 | AE13: =P13/Z13-1 -> 0 | AF13: =Q13/AA13-1 -> 0 | AG13: =R13/AB13-1 -> 0 | AH13: =S13/AC13-1 -> -0.011293405 | AN13: 44195 | AO13: =VLOOKUP($AN13,$A$3:$S$1552,O$1,0) -> 1.4638865 | AP13: =VLOOKUP($AN13,$A$3:$S$1552,P$1,0) -> 1.3927331 | AQ13: =VLOOKUP($AN13,$A$3:$S$1552,Q$1,0) -> 1.5350399 | AR13: =VLOOKUP($AN13,$A$3:$S$1552,R$1,0) -> 1.6069209 | AS13: =VLOOKUP($AN13,$A$3:$S$1552,S$1,0) -> 1.2172569 | AT13: 2020年 | AU13: =AO13/AO12-1 -> 0.46388651 | AV13: =AP13/AP12-1 -> 0.39273307 | AW13: =AQ13/AQ12-1 -> 0.53503995 | AX13: =AR13/AR12-1 -> 0.60692087 | AY13: =AS13/AS12-1 -> 0.2172569 | AZ13: ='增值-指数增强'!AE10 -> 0.29090822 | BA13: =增值序列!J1538 -> 0.43354675
A14: 43847 | B14: =[1]!thsiFinD("ths_int_chg_ratio_index",B$1,$A$4,$A14,101) -> 4.5133835 | C14: =[1]!thsiFinD("ths_int_chg_ratio_index",C$1,$A$4,$A14,101) -> 11.95677 | D14: =[1]!thsiFinD("ths_int_chg_ratio_index",D$1,$A$4,$A14,101) -> 21.470567 | E14: =[1]!thsiFinD("ths_int_chg_ratio_index",E$1,$A$4,$A14,101) -> 4.9410997 | F14: =[1]!thsiFinD("ths_adjustment_nvg_ratio_fund",F$1,$A$4,$A14,101) -> 9.699202 | G14: =[1]!thsiFinD("ths_adjustment_nvg_ratio_fund",G$1,$A$4,$A14,101) -> 7.3212259 | H14: =[1]!thsiFinD("ths_adjustment_nvg_ratio_fund",H$1,$A$4,$A14,101) -> 8.0769231 | I14: =[1]!thsiFinD("ths_adjustment_nvg_ratio_fund",I$1,$A$4,$A14,101) -> 5.2734375 | J14: =50%*K14+50%*L14 -> 0.091565761 | K14: =SUMPRODUCT(B14:E14,B$3:E$3)/100 -> 0.10720455 | L14: =SUMPRODUCT(F14:I14,F$3:I$3)/100 -> 0.075926971 | M14: =[1]!thsiFinD("ths_int_chg_ratio_index",M$1,$A$4,$A14,101)/100 -> 0.1261706 | N14: =[1]!thsiFinD("ths_int_chg_ratio_index",N$1,$A$4,$A14,101)/100 -> 0.0068688928 | O14: =J14+1 -> 1.0915658 | P14: =K14+1 -> 1.1072046 | Q14: =L14+1 -> 1.075927 | R14: =M14+1 -> 1.1261706 | S14: =N14+1 -> 1.0068689 | T14: =O14/O13-1 -> 0.010973595 | U14: =P14/P13-1 -> 0.020426113 | V14: =Q14/Q13-1 -> 0.0014273948 | W14: =R14/R13-1 -> 0.033924541 | X14: =S14/S13-1 -> 0.00028077224 | Y14: =MAX(O$4:O14) -> 1.0915658 | Z14: =MAX(P$4:P14) -> 1.1072046 | AA14: =MAX(Q$4:Q14) -> 1.075927 | AB14: =MAX(R$4:R14) -> 1.1261706 | AC14: =MAX(S$4:S14) -> 1.0180839 | AD14: =O14/Y14-1 -> 0 | AE14: =P14/Z14-1 -> 0 | AF14: =Q14/AA14-1 -> 0 | AG14: =R14/AB14-1 -> 0 | AH14: =S14/AC14-1 -> -0.011015804 | AN14: 44561 | AO14: =VLOOKUP($AN14,$A$3:$S$1552,O$1,0) -> 1.8179474 | AP14: =VLOOKUP($AN14,$A$3:$S$1552,P$1,0) -> 1.6474115 | AQ14: =VLOOKUP($AN14,$A$3:$S$1552,Q$1,0) -> 1.9884833 | AR14: =VLOOKUP($AN14,$A$3:$S$1552,R$1,0) -> 1.5796178 | AS14: =VLOOKUP($AN14,$A$3:$S$1552,S$1,0) -> 1.2301716 | AT14: 2021年 | AU14: =AO14/AO13-1 -> 0.24186361 | AV14: =AP14/AP13-1 -> 0.18286235 | AW14: =AQ14/AQ13-1 -> 0.29539513 | AX14: =AR14/AR13-1 -> -0.016990935 | AY14: =AS14/AS13-1 -> 0.010609659 | AZ14: ='增值-指数增强'!AE11 -> 0.18648292 | BA14: =增值序列!J1539 -> 0.24621908
A15: 43850 | B15: =[1]!thsiFinD("ths_int_chg_ratio_index",B$1,$A$4,$A15,101) -> 7.6461889 | C15: =[1]!thsiFinD("ths_int_chg_ratio_index",C$1,$A$4,$A15,101) -> 17.862162 | D15: =[1]!thsiFinD("ths_int_chg_ratio_index",D$1,$A$4,$A15,101) -> 21.651558 | E15: =[1]!thsiFinD("ths_int_chg_ratio_index",E$1,$A$4,$A15,101) -> 7.9663259 | F15: =[1]!thsiFinD("ths_adjustment_nvg_ratio_fund",F$1,$A$4,$A15,101) -> 12.277471 | G15: =[1]!thsiFinD("ths_adjustment_nvg_ratio_fund",G$1,$A$4,$A15,101) -> 10.385925 | H15: =[1]!thsiFinD("ths_adjustment_nvg_ratio_fund",H$1,$A$4,$A15,101) -> 12.846154 | I15: =[1]!thsiFinD("ths_adjustment_nvg_ratio_fund",I$1,$A$4,$A15,101) -> 7.7148438 | J15: =50%*K15+50%*L15 -> 0.12293828 | K15: =SUMPRODUCT(B15:E15,B$3:E$3)/100 -> 0.13781559 | L15: =SUMPRODUCT(F15:I15,F$3:I$3)/100 -> 0.10806098 | M15: =[1]!thsiFinD("ths_int_chg_ratio_index",M$1,$A$4,$A15,101)/100 -> 0.15158528 | N15: =[1]!thsiFinD("ths_int_chg_ratio_index",N$1,$A$4,$A15,101)/100 -> 0.01599346 | O15: =J15+1 -> 1.1229383 | P15: =K15+1 -> 1.1378156 | Q15: =L15+1 -> 1.108061 | R15: =M15+1 -> 1.1515853 | S15: =N15+1 -> 1.0159935 | T15: =O15/O14-1 -> 0.028740846 | U15: =P15/P14-1 -> 0.027647135 | V15: =Q15/Q14-1 -> 0.029866351 | W15: =R15/R14-1 -> 0.022567352 | X15: =S15/S14-1 -> 0.0090623192 | Y15: =MAX(O$4:O15) -> 1.1229383 | Z15: =MAX(P$4:P15) -> 1.1378156 | AA15: =MAX(Q$4:Q15) -> 1.108061 | AB15: =MAX(R$4:R15) -> 1.1515853 | AC15: =MAX(S$4:S15) -> 1.0180839 | AD15: =O15/Y15-1 -> 0 | AE15: =P15/Z15-1 -> 0 | AF15: =Q15/AA15-1 -> 0 | AG15: =R15/AB15-1 -> 0 | AH15: =S15/AC15-1 -> -0.0020533135 | AN15: 44925 | AO15: =VLOOKUP($AN15,$A$3:$S$1552,O$1,0) -> 1.333535 | AP15: =VLOOKUP($AN15,$A$3:$S$1552,P$1,0) -> 1.1447699 | AQ15: =VLOOKUP($AN15,$A$3:$S$1552,Q$1,0) -> 1.5223002 | AR15: =VLOOKUP($AN15,$A$3:$S$1552,R$1,0) -> 1.1313812 | AS15: =VLOOKUP($AN15,$A$3:$S$1552,S$1,0) -> 0.96794721 | AT15: 2022年 | AU15: =AO15/AO14-1 -> -0.26646114 | AV15: =AP15/AP14-1 -> -0.30510994 | AW15: =AQ15/AQ14-1 -> -0.23444153 | AX15: =AR15/AR14-1 -> -0.28376269 | AY15: =AS15/AS14-1 -> -0.21316081 | AZ15: ='增值-指数增强'!AE12 -> -0.19298452 | BA15: =增值序列!J1540 -> -0.21636882
A16: 43851 | B16: =[1]!thsiFinD("ths_int_chg_ratio_index",B$1,$A$4,$A16,101) -> 6.3666199 | C16: =[1]!thsiFinD("ths_int_chg_ratio_index",C$1,$A$4,$A16,101) -> 18.120939 | D16: =[1]!thsiFinD("ths_int_chg_ratio_index",D$1,$A$4,$A16,101) -> 17.190034 | E16: =[1]!thsiFinD("ths_int_chg_ratio_index",E$1,$A$4,$A16,101) -> 6.9387866 | F16: =[1]!thsiFinD("ths_adjustment_nvg_ratio_fund",F$1,$A$4,$A16,101) -> 10.804174 | G16: =[1]!thsiFinD("ths_adjustment_nvg_ratio_fund",G$1,$A$4,$A16,101) -> 9.9886493 | H16: =[1]!thsiFinD("ths_adjustment_nvg_ratio_fund",H$1,$A$4,$A16,101) -> 14 | I16: =[1]!thsiFinD("ths_adjustment_nvg_ratio_fund",I$1,$A$4,$A16,101) -> 6.9335938 | J16: =50%*K16+50%*L16 -> 0.1129285 | K16: =SUMPRODUCT(B16:E16,B$3:E$3)/100 -> 0.12154095 | L16: =SUMPRODUCT(F16:I16,F$3:I$3)/100 -> 0.10431604 | M16: =[1]!thsiFinD("ths_int_chg_ratio_index",M$1,$A$4,$A16,101)/100 -> 0.13440042 | N16: =[1]!thsiFinD("ths_int_chg_ratio_index",N$1,$A$4,$A16,101)/100 -> 5.0600554e-05 | O16: =J16+1 -> 1.1129285 | P16: =K16+1 -> 1.121541 | Q16: =L16+1 -> 1.104316 | R16: =M16+1 -> 1.1344004 | S16: =N16+1 -> 1.0000506 | T16: =O16/O15-1 -> -0.0089139251 | U16: =P16/P15-1 -> -0.014303403 | V16: =Q16/Q15-1 -> -0.0033797241 | W16: =R16/R15-1 -> -0.014922787 | X16: =S16/S15-1 -> -0.015691892 | Y16: =MAX(O$4:O16) -> 1.1229383 | Z16: =MAX(P$4:P16) -> 1.1378156 | AA16: =MAX(Q$4:Q16) -> 1.108061 | AB16: =MAX(R$4:R16) -> 1.1515853 | AC16: =MAX(S$4:S16) -> 1.0180839 | AD16: =O16/Y16-1 -> -0.0089139251 | AE16: =P16/Z16-1 -> -0.014303403 | AF16: =Q16/AA16-1 -> -0.0033797241 | AG16: =R16/AB16-1 -> -0.014922787 | AH16: =S16/AC16-1 -> -0.017712985 | AN16: 45289 | AO16: =VLOOKUP($AN16,$A$3:$S$1552,O$1,0) -> 1.2927999 | AP16: =VLOOKUP($AN16,$A$3:$S$1552,P$1,0) -> 1.0514057 | AQ16: =VLOOKUP($AN16,$A$3:$S$1552,Q$1,0) -> 1.534194 | AR16: =VLOOKUP($AN16,$A$3:$S$1552,R$1,0) -> 0.9365391 | AS16: =VLOOKUP($AN16,$A$3:$S$1552,S$1,0) -> 0.86754 | AT16: 2023年 | AU16: =AO16/AO15-1 -> -0.030546776 | AV16: =AP16/AP15-1 -> -0.081557186 | AW16: =AQ16/AQ15-1 -> 0.0078130568 | AX16: =AR16/AR15-1 -> -0.17221614 | AY16: =AS16/AS15-1 -> -0.10373211 | AZ16: ='增值-指数增强'!AE13 -> -0.018795985 | BA16: =增值序列!J1541 -> -0.0048819712
A17: 43852 | B17: =[1]!thsiFinD("ths_int_chg_ratio_index",B$1,$A$4,$A17,101) -> 8.2738664 | C17: =[1]!thsiFinD("ths_int_chg_ratio_index",C$1,$A$4,$A17,101) -> 25.122288 | D17: =[1]!thsiFinD("ths_int_chg_ratio_index",D$1,$A$4,$A17,101) -> 22.045312 | E17: =[1]!thsiFinD("ths_int_chg_ratio_index",E$1,$A$4,$A17,101) -> 9.4073621 | F17: =[1]!thsiFinD("ths_adjustment_nvg_ratio_fund",F$1,$A$4,$A17,101) -> 13.627993 | G17: =[1]!thsiFinD("ths_adjustment_nvg_ratio_fund",G$1,$A$4,$A17,101) -> 13.337117 | H17: =[1]!thsiFinD("ths_adjustment_nvg_ratio_fund",H$1,$A$4,$A17,101) -> 18.153846 | I17: =[1]!thsiFinD("ths_adjustment_nvg_ratio_fund",I$1,$A$4,$A17,101) -> 9.375 | J17: =50%*K17+50%*L17 -> 0.14917848 | K17: =SUMPRODUCT(B17:E17,B$3:E$3)/100 -> 0.16212207 | L17: =SUMPRODUCT(F17:I17,F$3:I$3)/100 -> 0.13623489 | M17: =[1]!thsiFinD("ths_int_chg_ratio_index",M$1,$A$4,$A17,101)/100 -> 0.16302224 | N17: =[1]!thsiFinD("ths_int_chg_ratio_index",N$1,$A$4,$A17,101)/100 -> 0.0055747899 | O17: =J17+1 -> 1.1491785 | P17: =K17+1 -> 1.1621221 | Q17: =L17+1 -> 1.1362349 | R17: =M17+1 -> 1.1630222 | S17: =N17+1 -> 1.0055748 | T17: =O17/O16-1 -> 0.032571709 | U17: =P17/P16-1 -> 0.036183361 | V17: =Q17/Q16-1 -> 0.028903724 | W17: =R17/R16-1 -> 0.02523079 | X17: =S17/S16-1 -> 0.0055239099 | Y17: =MAX(O$4:O17) -> 1.1491785 | Z17: =MAX(P$4:P17) -> 1.1621221 | AA17: =MAX(Q$4:Q17) -> 1.1362349 | AB17: =MAX(R$4:R17) -> 1.1630222 | AC17: =MAX(S$4:S17) -> 1.0180839 | AD17: =O17/Y17-1 -> 0 | AE17: =P17/Z17-1 -> 0 | AF17: =Q17/AA17-1 -> 0 | AG17: =R17/AB17-1 -> 0 | AH17: =S17/AC17-1 -> -0.01228692 | AN17: 45657 | AO17: =VLOOKUP($AN17,$A$3:$S$1552,O$1,0) -> 1.6085686 | AP17: =VLOOKUP($AN17,$A$3:$S$1552,P$1,0) -> 1.2441342 | AQ17: =VLOOKUP($AN17,$A$3:$S$1552,Q$1,0) -> 1.973003 | AR17: =VLOOKUP($AN17,$A$3:$S$1552,R$1,0) -> 0.98554792 | AS17: =VLOOKUP($AN17,$A$3:$S$1552,S$1,0) -> 0.97340431 | AT17: 2024年 | AU17: =AO17/AO16-1 -> 0.24425181 | AV17: =AP17/AP16-1 -> 0.18330555 | AW17: =AQ17/AQ16-1 -> 0.28601918 | AX17: =AR17/AR16-1 -> 0.052329716 | AY17: =AS17/AS16-1 -> 0.12202815 | AZ17: ='增值-指数增强'!AE14 -> 0.094822329 | BA17: =增值序列!J1542 -> 0.20307703
A18: 43853 | B18: =[1]!thsiFinD("ths_int_chg_ratio_index",B$1,$A$4,$A18,101) -> 3.2796959 | C18: =[1]!thsiFinD("ths_int_chg_ratio_index",C$1,$A$4,$A18,101) -> 20.53023 | D18: =[1]!thsiFinD("ths_int_chg_ratio_index",D$1,$A$4,$A18,101) -> 17.885125 | E18: =[1]!thsiFinD("ths_int_chg_ratio_index",E$1,$A$4,$A18,101) -> 5.8190382 | F18: =[1]!thsiFinD("ths_adjustment_nvg_ratio_fund",F$1,$A$4,$A18,101) -> 10.006139 | G18: =[1]!thsiFinD("ths_adjustment_nvg_ratio_fund",G$1,$A$4,$A18,101) -> 11.180477 | H18: =[1]!thsiFinD("ths_adjustment_nvg_ratio_fund",H$1,$A$4,$A18,101) -> 14.076923 | I18: =[1]!thsiFinD("ths_adjustment_nvg_ratio_fund",I$1,$A$4,$A18,101) -> 6.4453125 | J18: =50%*K18+50%*L18 -> 0.11152867 | K18: =SUMPRODUCT(B18:E18,B$3:E$3)/100 -> 0.11878522 | L18: =SUMPRODUCT(F18:I18,F$3:I$3)/100 -> 0.10427213 | M18: =[1]!thsiFinD("ths_int_chg_ratio_index",M$1,$A$4,$A18,101)/100 -> 0.12630209 | N18: =[1]!thsiFinD("ths_int_chg_ratio_index",N$1,$A$4,$A18,101)/100 -> -0.026695258 | O18: =J18+1 -> 1.1115287 | P18: =K18+1 -> 1.1187852 | Q18: =L18+1 -> 1.1042721 | R18: =M18+1 -> 1.1263021 | S18: =N18+1 -> 0.97330474 | T18: =O18/O17-1 -> -0.032762366 | U18: =P18/P17-1 -> -0.037291133 | V18: =Q18/Q17-1 -> -0.028130417 | W18: =R18/R17-1 -> -0.031573045 | X18: =S18/S17-1 -> -0.032091147 | Y18: =MAX(O$4:O18) -> 1.1491785 | Z18: =MAX(P$4:P18) -> 1.1621221 | AA18: =MAX(Q$4:Q18) -> 1.1362349 | AB18: =MAX(R$4:R18) -> 1.1630222 | AC18: =MAX(S$4:S18) -> 1.0180839 | AD18: =O18/Y18-1 -> -0.032762366 | AE18: =P18/Z18-1 -> -0.037291133 | AF18: =Q18/AA18-1 -> -0.028130417 | AG18: =R18/AB18-1 -> -0.031573045 | AH18: =S18/AC18-1 -> -0.043983766 | AN18: 46022 | AO18: =VLOOKUP($AN18,$A$3:$S$1552,O$1,0) -> 2.9406503 | AP18: =VLOOKUP($AN18,$A$3:$S$1552,P$1,0) -> 2.0864853 | AQ18: =VLOOKUP($AN18,$A$3:$S$1552,Q$1,0) -> 3.7948152 | AR18: =VLOOKUP($AN18,$A$3:$S$1552,R$1,0) -> 1.3915357 | AS18: =VLOOKUP($AN18,$A$3:$S$1552,S$1,0) -> 1.1767276 | AT18: 2025年 | AU18: =AO18/AO17-1 -> 0.82811622 | AV18: =AP18/AP17-1 -> 0.67705812 | AW18: =AQ18/AQ17-1 -> 0.92337028 | AX18: =AR18/AR17-1 -> 0.41194122 | AY18: =AS18/AS17-1 -> 0.20887859 | AZ18: ='增值-指数增强'!AE15 -> 0.39265658 | BA18: =增值序列!J1543 -> 0.71314067
A19: 43864 | B19: =[1]!thsiFinD("ths_int_chg_ratio_index",B$1,$A$4,$A19,101) -> -6.2892155 | C19: =[1]!thsiFinD("ths_int_chg_ratio_index",C$1,$A$4,$A19,101) -> 8.475285 | D19: =[1]!thsiFinD("ths_int_chg_ratio_index",D$1,$A$4,$A19,101) -> 1.0617487 | E19: =[1]!thsiFinD("ths_int_chg_ratio_index",E$1,$A$4,$A19,101) -> -1.0038267 | F19: =[1]!thsiFinD("ths_adjustment_nvg_ratio_fund",F$1,$A$4,$A19,101) -> 2.0257827 | G19: =[1]!thsiFinD("ths_adjustment_nvg_ratio_fund",G$1,$A$4,$A19,101) -> 4.3132804 | H19: =[1]!thsiFinD("ths_adjustment_nvg_ratio_fund",H$1,$A$4,$A19,101) -> 4.8461538 | I19: =[1]!thsiFinD("ths_adjustment_nvg_ratio_fund",I$1,$A$4,$A19,101) -> -1.3671875 | J19: =50%*K19+50%*L19 -> 0.015077526 | K19: =SUMPRODUCT(B19:E19,B$3:E$3)/100 -> 0.0056099789 | L19: =SUMPRODUCT(F19:I19,F$3:I$3)/100 -> 0.024545073 | M19: =[1]!thsiFinD("ths_int_chg_ratio_index",M$1,$A$4,$A19,101)/100 -> 0.011739241 | N19: =[1]!thsiFinD("ths_int_chg_ratio_index",N$1,$A$4,$A19,101)/100 -> -0.10531309 | O19: =J19+1 -> 1.0150775 | P19: =K19+1 -> 1.00561 | Q19: =L19+1 -> 1.0245451 | R19: =M19+1 -> 1.0117392 | S19: =N19+1 -> 0.89468691 | T19: =O19/O18-1 -> -0.086773424 | U19: =P19/P18-1 -> -0.10115904 | V19: =Q19/Q18-1 -> -0.072198738 | W19: =R19/R18-1 -> -0.10171591 | X19: =S19/S18-1 -> -0.080774116 | Y19: =MAX(O$4:O19) -> 1.1491785 | Z19: =MAX(P$4:P19) -> 1.1621221 | AA19: =MAX(Q$4:Q19) -> 1.1362349 | AB19: =MAX(R$4:R19) -> 1.1630222 | AC19: =MAX(S$4:S19) -> 1.0180839 | AD19: =O19/Y19-1 -> -0.11669289 | AE19: =P19/Z19-1 -> -0.13467784 | AF19: =Q19/AA19-1 -> -0.098298175 | AG19: =R19/AB19-1 -> -0.13007748 | AH19: =S19/AC19-1 -> -0.12120513 | AN19: 46142 | AO19: =VLOOKUP($AN19,$A$3:$S$1552,O$1,0) -> 3.741689 | AP19: =VLOOKUP($AN19,$A$3:$S$1552,P$1,0) -> 2.5866241 | AQ19: =VLOOKUP($AN19,$A$3:$S$1552,Q$1,0) -> 4.8967538 | AR19: =VLOOKUP($AN19,$A$3:$S$1552,R$1,0) -> 1.5417244 | AS19: =VLOOKUP($AN19,$A$3:$S$1552,S$1,0) -> 1.2473463 | AT19: 2026年YTD | AU19: =AO19/AO18-1 -> 0.27240189 | AV19: =AP19/AP18-1 -> 0.23970397 | AW19: =AQ19/AQ18-1 -> 0.29038003 | AX19: =AR19/AR18-1 -> 0.10793013 | AY19: =AS19/AS18-1 -> 0.060012787 | AZ19: ='增值-指数增强'!AE16 -> 0.12620206 | BA19: =增值序列!J1544 -> 0.23790549
A20: 43865 | B20: =[1]!thsiFinD("ths_int_chg_ratio_index",B$1,$A$4,$A20,101) -> -6.1434311 | C20: =[1]!thsiFinD("ths_int_chg_ratio_index",C$1,$A$4,$A20,101) -> 13.924437 | D20: =[1]!thsiFinD("ths_int_chg_ratio_index",D$1,$A$4,$A20,101) -> 13.09259 | E20: =[1]!thsiFinD("ths_int_chg_ratio_index",E$1,$A$4,$A20,101) -> 4.2740635 | F20: =[1]!thsiFinD("ths_adjustment_nvg_ratio_fund",F$1,$A$4,$A20,101) -> 6.8753837 | G20: =[1]!thsiFinD("ths_adjustment_nvg_ratio_fund",G$1,$A$4,$A20,101) -> 9.7616345 | H20: =[1]!thsiFinD("ths_adjustment_nvg_ratio_fund",H$1,$A$4,$A20,101) -> 7.5384615 | I20: =[1]!thsiFinD("ths_adjustment_nvg_ratio_fund",I$1,$A$4,$A20,101) -> 2.34375 | J20: =50%*K20+50%*L20 -> 0.064583611 | K20: =SUMPRODUCT(B20:E20,B$3:E$3)/100 -> 0.062869148 | L20: =SUMPRODUCT(F20:I20,F$3:I$3)/100 -> 0.066298074 | M20: =[1]!thsiFinD("ths_int_chg_ratio_index",M$1,$A$4,$A20,101)/100 -> 0.077379001 | N20: =[1]!thsiFinD("ths_int_chg_ratio_index",N$1,$A$4,$A20,101)/100 -> -0.083669939 | O20: =J20+1 -> 1.0645836 | P20: =K20+1 -> 1.0628691 | Q20: =L20+1 -> 1.0662981 | R20: =M20+1 -> 1.077379 | S20: =N20+1 -> 0.91633006 | T20: =O20/O19-1 -> 0.048770743 | U20: =P20/P19-1 -> 0.056939738 | V20: =Q20/Q19-1 -> 0.040752722 | W20: =R20/R19-1 -> 0.064878139 | X20: =S20/S19-1 -> 0.024190752 | Y20: =MAX(O$4:O20) -> 1.1491785 | Z20: =MAX(P$4:P20) -> 1.1621221 | AA20: =MAX(Q$4:Q20) -> 1.1362349 | AB20: =MAX(R$4:R20) -> 1.1630222 | AC20: =MAX(S$4:S20) -> 1.0180839 | AD20: =O20/Y20-1 -> -0.073613342 | AE20: =P20/Z20-1 -> -0.085406624 | AF20: =Q20/AA20-1 -> -0.061551371 | AG20: =R20/AB20-1 -> -0.073638523 | AH20: =S20/AC20-1 -> -0.099946423
A21: 43866 | B21: =[1]!thsiFinD("ths_int_chg_ratio_index",B$1,$A$4,$A21,101) -> -4.3421664 | C21: =[1]!thsiFinD("ths_int_chg_ratio_index",C$1,$A$4,$A21,101) -> 15.184925 | D21: =[1]!thsiFinD("ths_int_chg_ratio_index",D$1,$A$4,$A21,101) -> 18.033263 | E21: =[1]!thsiFinD("ths_int_chg_ratio_index",E$1,$A$4,$A21,101) -> 7.889151 | F21: =[1]!thsiFinD("ths_adjustment_nvg_ratio_fund",F$1,$A$4,$A21,101) -> 8.9011664 | G21: =[1]!thsiFinD("ths_adjustment_nvg_ratio_fund",G$1,$A$4,$A21,101) -> 11.577753 | H21: =[1]!thsiFinD("ths_adjustment_nvg_ratio_fund",H$1,$A$4,$A21,101) -> 8.5384615 | I21: =[1]!thsiFinD("ths_adjustment_nvg_ratio_fund",I$1,$A$4,$A21,101) -> 3.7109375 | J21: =50%*K21+50%*L21 -> 0.086866862 | K21: =SUMPRODUCT(B21:E21,B$3:E$3)/100 -> 0.09191293 | L21: =SUMPRODUCT(F21:I21,F$3:I$3)/100 -> 0.081820795 | M21: =[1]!thsiFinD("ths_int_chg_ratio_index",M$1,$A$4,$A21,101)/100 -> 0.10735035 | N21: =[1]!thsiFinD("ths_int_chg_ratio_index",N$1,$A$4,$A21,101)/100 -> -0.070136997 | O21: =J21+1 -> 1.0868669 | P21: =K21+1 -> 1.0919129 | Q21: =L21+1 -> 1.0818208 | R21: =M21+1 -> 1.1073503 | S21: =N21+1 -> 0.929863 | T21: =O21/O20-1 -> 0.020931424 | U21: =P21/P20-1 -> 0.02732583 | V21: =Q21/Q20-1 -> 0.014557581 | W21: =R21/R20-1 -> 0.027818758 | X21: =S21/S20-1 -> 0.014768633 | Y21: =MAX(O$4:O21) -> 1.1491785 | Z21: =MAX(P$4:P21) -> 1.1621221 | AA21: =MAX(Q$4:Q21) -> 1.1362349 | AB21: =MAX(R$4:R21) -> 1.1630222 | AC21: =MAX(S$4:S21) -> 1.0180839 | AD21: =O21/Y21-1 -> -0.05422275 | AE21: =P21/Z21-1 -> -0.060414601 | AF21: =Q21/AA21-1 -> -0.047889829 | AG21: =R21/AB21-1 -> -0.047868297 | AH21: =S21/AC21-1 -> -0.086653862
A22: 43867 | B22: =[1]!thsiFinD("ths_int_chg_ratio_index",B$1,$A$4,$A22,101) -> -2.2096132 | C22: =[1]!thsiFinD("ths_int_chg_ratio_index",C$1,$A$4,$A22,101) -> 20.147353 | D22: =[1]!thsiFinD("ths_int_chg_ratio_index",D$1,$A$4,$A22,101) -> 21.479737 | E22: =[1]!thsiFinD("ths_int_chg_ratio_index",E$1,$A$4,$A22,101) -> 11.949749 | F22: =[1]!thsiFinD("ths_adjustment_nvg_ratio_fund",F$1,$A$4,$A22,101) -> 12.952732 | G22: =[1]!thsiFinD("ths_adjustment_nvg_ratio_fund",G$1,$A$4,$A22,101) -> 14.982974 | H22: =[1]!thsiFinD("ths_adjustment_nvg_ratio_fund",H$1,$A$4,$A22,101) -> 11.153846 | I22: =[1]!thsiFinD("ths_adjustment_nvg_ratio_fund",I$1,$A$4,$A22,101) -> 6.9335938 | J22: =50%*K22+50%*L22 -> 0.12173796 | K22: =SUMPRODUCT(B22:E22,B$3:E$3)/100 -> 0.12841806 | L22: =SUMPRODUCT(F22:I22,F$3:I$3)/100 -> 0.11505786 | M22: =[1]!thsiFinD("ths_int_chg_ratio_index",M$1,$A$4,$A22,101)/100 -> 0.14059159 | N22: =[1]!thsiFinD("ths_int_chg_ratio_index",N$1,$A$4,$A22,101)/100 -> -0.050005646 | O22: =J22+1 -> 1.121738 | P22: =K22+1 -> 1.1284181 | Q22: =L22+1 -> 1.1150579 | R22: =M22+1 -> 1.1405916 | S22: =N22+1 -> 0.94999435 | T22: =O22/O21-1 -> 0.032084059 | U22: =P22/P21-1 -> 0.033432275 | V22: =Q22/Q21-1 -> 0.030723267 | W22: =R22/R21-1 -> 0.03001872 | X22: =S22/S21-1 -> 0.021649803 | Y22: =MAX(O$4:O22) -> 1.1491785 | Z22: =MAX(P$4:P22) -> 1.1621221 | AA22: =MAX(Q$4:Q22) -> 1.1362349 | AB22: =MAX(R$4:R22) -> 1.1630222 | AC22: =MAX(S$4:S22) -> 1.0180839 | AD22: =O22/Y22-1 -> -0.023878377 | AE22: =P22/Z22-1 -> -0.029002124 | AF22: =Q22/AA22-1 -> -0.018637894 | AG22: =R22/AB22-1 -> -0.019286522 | AH22: =S22/AC22-1 -> -0.066880098
A23: 43868 | B23: =[1]!thsiFinD("ths_int_chg_ratio_index",B$1,$A$4,$A23,101) -> -0.59832687 | C23: =[1]!thsiFinD("ths_int_chg_ratio_index",C$1,$A$4,$A23,101) -> 24.86601 | D23: =[1]!thsiFinD("ths_int_chg_ratio_index",D$1,$A$4,$A23,101) -> 28.246228 | E23: =[1]!thsiFinD("ths_int_chg_ratio_index",E$1,$A$4,$A23,101) -> 11.420057 | F23: =[1]!thsiFinD("ths_adjustment_nvg_ratio_fund",F$1,$A$4,$A23,101) -> 16.329036 | G23: =[1]!thsiFinD("ths_adjustment_nvg_ratio_fund",G$1,$A$4,$A23,101) -> 16.00454 | H23: =[1]!thsiFinD("ths_adjustment_nvg_ratio_fund",H$1,$A$4,$A23,101) -> 13.076923 | I23: =[1]!thsiFinD("ths_adjustment_nvg_ratio_fund",I$1,$A$4,$A23,101) -> 7.9101562 | J23: =50%*K23+50%*L23 -> 0.14656828 | K23: =SUMPRODUCT(B23:E23,B$3:E$3)/100 -> 0.15983492 | L23: =SUMPRODUCT(F23:I23,F$3:I$3)/100 -> 0.13330164 | M23: =[1]!thsiFinD("ths_int_chg_ratio_index",M$1,$A$4,$A23,101)/100 -> 0.16378509 | N23: =[1]!thsiFinD("ths_int_chg_ratio_index",N$1,$A$4,$A23,101)/100 -> -0.048025453 | O23: =J23+1 -> 1.1465683 | P23: =K23+1 -> 1.1598349 | Q23: =L23+1 -> 1.1333016 | R23: =M23+1 -> 1.1637851 | S23: =N23+1 -> 0.95197455 | T23: =O23/O22-1 -> 0.022135578 | U23: =P23/P22-1 -> 0.027841507 | V23: =Q23/Q22-1 -> 0.016361282 | W23: =R23/R22-1 -> 0.020334625 | X23: =S23/S22-1 -> 0.002084426 | Y23: =MAX(O$4:O23) -> 1.1491785 | Z23: =MAX(P$4:P23) -> 1.1621221 | AA23: =MAX(Q$4:Q23) -> 1.1362349 | AB23: =MAX(R$4:R23) -> 1.1637851 | AC23: =MAX(S$4:S23) -> 1.0180839 | AD23: =O23/Y23-1 -> -0.0022713609 | AE23: =P23/Z23-1 -> -0.0019680794 | AF23: =Q23/AA23-1 -> -0.0025815522 | AG23: =R23/AB23-1 -> 0 | AH23: =S23/AC23-1 -> -0.064935079 | AT23: 产业趋势指数组合：从十五五规划支柱产业出发，以创业板50和科创板50为底仓，叠加两条投资线，一是参与全球AI产业链的企业，比如算力基建设施，比如光、存、电等；二是自主创新产业链，包括先进制程国产化、匹配国产大模型的AI基建。
A24: 43871 | B24: =[1]!thsiFinD("ths_int_chg_ratio_index",B$1,$A$4,$A24,101) -> 0.14816717 | C24: =[1]!thsiFinD("ths_int_chg_ratio_index",C$1,$A$4,$A24,101) -> 22.628644 | D24: =[1]!thsiFinD("ths_int_chg_ratio_index",D$1,$A$4,$A24,101) -> 29.667535 | E24: =[1]!thsiFinD("ths_int_chg_ratio_index",E$1,$A$4,$A24,101) -> 13.335072 | F24: =[1]!thsiFinD("ths_adjustment_nvg_ratio_fund",F$1,$A$4,$A24,101) -> 16.635973 | G24: =[1]!thsiFinD("ths_adjustment_nvg_ratio_fund",G$1,$A$4,$A24,101) -> 16.45857 | H24: =[1]!thsiFinD("ths_adjustment_nvg_ratio_fund",H$1,$A$4,$A24,101) -> 12.153846 | I24: =[1]!thsiFinD("ths_adjustment_nvg_ratio_fund",I$1,$A$4,$A24,101) -> 8.0078125 | J24: =50%*K24+50%*L24 -> 0.14879452 | K24: =SUMPRODUCT(B24:E24,B$3:E$3)/100 -> 0.16444855 | L24: =SUMPRODUCT(F24:I24,F$3:I$3)/100 -> 0.1331405 | M24: =[1]!thsiFinD("ths_int_chg_ratio_index",M$1,$A$4,$A24,101)/100 -> 0.18013466 | N24: =[1]!thsiFinD("ths_int_chg_ratio_index",N$1,$A$4,$A24,101)/100 -> -0.042336588 | O24: =J24+1 -> 1.1487945 | P24: =K24+1 -> 1.1644485 | Q24: =L24+1 -> 1.1331405 | R24: =M24+1 -> 1.1801347 | S24: =N24+1 -> 0.95766341 | T24: =O24/O23-1 -> 0.0019416581 | U24: =P24/P23-1 -> 0.0039778274 | V24: =Q24/Q23-1 -> -0.00014218278 | W24: =R24/R23-1 -> 0.014048617 | X24: =S24/S23-1 -> 0.0059758591 | Y24: =MAX(O$4:O24) -> 1.1491785 | Z24: =MAX(P$4:P24) -> 1.1644485 | AA24: =MAX(Q$4:Q24) -> 1.1362349 | AB24: =MAX(R$4:R24) -> 1.1801347 | AC24: =MAX(S$4:S24) -> 1.0180839 | AD24: =O24/Y24-1 -> -0.00033411298 | AE24: =P24/Z24-1 -> 0 | AF24: =Q24/AA24-1 -> -0.0027233679 | AG24: =R24/AB24-1 -> 0 | AH24: =S24/AC24-1 -> -0.059347263 | AT24: 代码 | AU24: 简称 | AV24: 配比
A25: 43872 | B25: =[1]!thsiFinD("ths_int_chg_ratio_index",B$1,$A$4,$A25,101) -> 0.058441244 | C25: =[1]!thsiFinD("ths_int_chg_ratio_index",C$1,$A$4,$A25,101) -> 23.050168 | D25: =[1]!thsiFinD("ths_int_chg_ratio_index",D$1,$A$4,$A25,101) -> 25.874566 | E25: =[1]!thsiFinD("ths_int_chg_ratio_index",E$1,$A$4,$A25,101) -> 12.387388 | F25: =[1]!thsiFinD("ths_adjustment_nvg_ratio_fund",F$1,$A$4,$A25,101) -> 16.206262 | G25: =[1]!thsiFinD("ths_adjustment_nvg_ratio_fund",G$1,$A$4,$A25,101) -> 16.855846 | H25: =[1]!thsiFinD("ths_adjustment_nvg_ratio_fund",H$1,$A$4,$A25,101) -> 14.692308 | I25: =[1]!thsiFinD("ths_adjustment_nvg_ratio_fund",I$1,$A$4,$A25,101) -> 8.7890625 | J25: =50%*K25+50%*L25 -> 0.14739255 | K25: =SUMPRODUCT(B25:E25,B$3:E$3)/100 -> 0.15342641 | L25: =SUMPRODUCT(F25:I25,F$3:I$3)/100 -> 0.14135869 | M25: =[1]!thsiFinD("ths_int_chg_ratio_index",M$1,$A$4,$A25,101)/100 -> 0.17187844 | N25: =[1]!thsiFinD("ths_int_chg_ratio_index",N$1,$A$4,$A25,101)/100 -> -0.036859152 | O25: =J25+1 -> 1.1473926 | P25: =K25+1 -> 1.1534264 | Q25: =L25+1 -> 1.1413587 | R25: =M25+1 -> 1.1718784 | S25: =N25+1 -> 0.96314085 | T25: =O25/O24-1 -> -0.0012203874 | U25: =P25/P24-1 -> -0.0094655436 | V25: =Q25/Q24-1 -> 0.0072525778 | W25: =R25/R24-1 -> -0.0069960003 | X25: =S25/S24-1 -> 0.0057195827 | Y25: =MAX(O$4:O25) -> 1.1491785 | Z25: =MAX(P$4:P25) -> 1.1644485 | AA25: =MAX(Q$4:Q25) -> 1.1413587 | AB25: =MAX(R$4:R25) -> 1.1801347 | AC25: =MAX(S$4:S25) -> 1.0180839 | AD25: =O25/Y25-1 -> -0.0015540927 | AE25: =P25/Z25-1 -> -0.0094655436 | AF25: =Q25/AA25-1 -> 0 | AG25: =R25/AB25-1 -> -0.0069960003 | AH25: =S25/AC25-1 -> -0.053967122 | AT25: 931160.CSI | AU25: 中证全指通信设备 | AV25: 0.25
A26: 43873 | B26: =[1]!thsiFinD("ths_int_chg_ratio_index",B$1,$A$4,$A26,101) -> 1.5574833 | C26: =[1]!thsiFinD("ths_int_chg_ratio_index",C$1,$A$4,$A26,101) -> 26.949843 | D26: =[1]!thsiFinD("ths_int_chg_ratio_index",D$1,$A$4,$A26,101) -> 32.261543 | E26: =[1]!thsiFinD("ths_int_chg_ratio_index",E$1,$A$4,$A26,101) -> 15.83974 | F26: =[1]!thsiFinD("ths_adjustment_nvg_ratio_fund",F$1,$A$4,$A26,101) -> 19.459791 | G26: =[1]!thsiFinD("ths_adjustment_nvg_ratio_fund",G$1,$A$4,$A26,101) -> 19.06924 | H26: =[1]!thsiFinD("ths_adjustment_nvg_ratio_fund",H$1,$A$4,$A26,101) -> 16.461538 | I26: =[1]!thsiFinD("ths_adjustment_nvg_ratio_fund",I$1,$A$4,$A26,101) -> 11.328125 | J26: =50%*K26+50%*L26 -> 0.17865913 | K26: =SUMPRODUCT(B26:E26,B$3:E$3)/100 -> 0.19152152 | L26: =SUMPRODUCT(F26:I26,F$3:I$3)/100 -> 0.16579674 | M26: =[1]!thsiFinD("ths_int_chg_ratio_index",M$1,$A$4,$A26,101)/100 -> 0.20788589 | N26: =[1]!thsiFinD("ths_int_chg_ratio_index",N$1,$A$4,$A26,101)/100 -> -0.026609627 | O26: =J26+1 -> 1.1786591 | P26: =K26+1 -> 1.1915215 | Q26: =L26+1 -> 1.1657967 | R26: =M26+1 -> 1.2078859 | S26: =N26+1 -> 0.97339037 | T26: =O26/O25-1 -> 0.027250115 | U26: =P26/P25-1 -> 0.033027781 | V26: =Q26/Q25-1 -> 0.02141136 | W26: =R26/R25-1 -> 0.030726274 | X26: =S26/S25-1 -> 0.010641772 | Y26: =MAX(O$4:O26) -> 1.1786591 | Z26: =MAX(P$4:P26) -> 1.1915215 | AA26: =MAX(Q$4:Q26) -> 1.1657967 | AB26: =MAX(R$4:R26) -> 1.2078859 | AC26: =MAX(S$4:S26) -> 1.0180839 | AD26: =O26/Y26-1 -> 0 | AE26: =P26/Z26-1 -> 0 | AF26: =Q26/AA26-1 -> 0 | AG26: =R26/AB26-1 -> 0 | AH26: =S26/AC26-1 -> -0.043899655 | AT26: 931743.CSI | AU26: 中证半导体材料设备 | AV26: 0.25
A27: 43874 | B27: =[1]!thsiFinD("ths_int_chg_ratio_index",B$1,$A$4,$A27,101) -> 0.58720758 | C27: =[1]!thsiFinD("ths_int_chg_ratio_index",C$1,$A$4,$A27,101) -> 29.866387 | D27: =[1]!thsiFinD("ths_int_chg_ratio_index",D$1,$A$4,$A27,101) -> 33.439068 | E27: =[1]!thsiFinD("ths_int_chg_ratio_index",E$1,$A$4,$A27,101) -> 14.764099 | F27: =[1]!thsiFinD("ths_adjustment_nvg_ratio_fund",F$1,$A$4,$A27,101) -> 19.214242 | G27: =[1]!thsiFinD("ths_adjustment_nvg_ratio_fund",G$1,$A$4,$A27,101) -> 18.444949 | H27: =[1]!thsiFinD("ths_adjustment_nvg_ratio_fund",H$1,$A$4,$A27,101) -> 16.769231 | I27: =[1]!thsiFinD("ths_adjustment_nvg_ratio_fund",I$1,$A$4,$A27,101) -> 11.132812 | J27: =50%*K27+50%*L27 -> 0.18027249 | K27: =SUMPRODUCT(B27:E27,B$3:E$3)/100 -> 0.1966419 | L27: =SUMPRODUCT(F27:I27,F$3:I$3)/100 -> 0.16390309 | M27: =[1]!thsiFinD("ths_int_chg_ratio_index",M$1,$A$4,$A27,101)/100 -> 0.20224524 | N27: =[1]!thsiFinD("ths_int_chg_ratio_index",N$1,$A$4,$A27,101)/100 -> -0.033199215 | O27: =J27+1 -> 1.1802725 | P27: =K27+1 -> 1.1966419 | Q27: =L27+1 -> 1.1639031 | R27: =M27+1 -> 1.2022452 | S27: =N27+1 -> 0.96680079 | T27: =O27/O26-1 -> 0.0013688143 | U27: =P27/P26-1 -> 0.0042973471 | V27: =Q27/Q26-1 -> -0.0016243402 | W27: =R27/R26-1 -> -0.0046698605 | X27: =S27/S26-1 -> -0.0067697278 | Y27: =MAX(O$4:O27) -> 1.1802725 | Z27: =MAX(P$4:P27) -> 1.1966419 | AA27: =MAX(Q$4:Q27) -> 1.1657967 | AB27: =MAX(R$4:R27) -> 1.2078859 | AC27: =MAX(S$4:S27) -> 1.0180839 | AD27: =O27/Y27-1 -> 0 | AE27: =P27/Z27-1 -> 0 | AF27: =Q27/AA27-1 -> -0.0016243402 | AG27: =R27/AB27-1 -> -0.0046698605 | AH27: =S27/AC27-1 -> -0.050372194 | AT27: 000688.SH | AU27: 科创50 | AV27: 0.25
A28: 43875 | B28: =[1]!thsiFinD("ths_int_chg_ratio_index",B$1,$A$4,$A28,101) -> 0.75497716 | C28: =[1]!thsiFinD("ths_int_chg_ratio_index",C$1,$A$4,$A28,101) -> 31.954376 | D28: =[1]!thsiFinD("ths_int_chg_ratio_index",D$1,$A$4,$A28,101) -> 30.155295 | E28: =[1]!thsiFinD("ths_int_chg_ratio_index",E$1,$A$4,$A28,101) -> 14.795638 | F28: =[1]!thsiFinD("ths_adjustment_nvg_ratio_fund",F$1,$A$4,$A28,101) -> 19.275629 | G28: =[1]!thsiFinD("ths_adjustment_nvg_ratio_fund",G$1,$A$4,$A28,101) -> 17.934166 | H28: =[1]!thsiFinD("ths_adjustment_nvg_ratio_fund",H$1,$A$4,$A28,101) -> 17.846154 | I28: =[1]!thsiFinD("ths_adjustment_nvg_ratio_fund",I$1,$A$4,$A28,101) -> 12.011719 | J28: =50%*K28+50%*L28 -> 0.18090994 | K28: =SUMPRODUCT(B28:E28,B$3:E$3)/100 -> 0.19415071 | L28: =SUMPRODUCT(F28:I28,F$3:I$3)/100 -> 0.16766917 | M28: =[1]!thsiFinD("ths_int_chg_ratio_index",M$1,$A$4,$A28,101)/100 -> 0.19138978 | N28: =[1]!thsiFinD("ths_int_chg_ratio_index",N$1,$A$4,$A28,101)/100 -> -0.027744949 | O28: =J28+1 -> 1.1809099 | P28: =K28+1 -> 1.1941507 | Q28: =L28+1 -> 1.1676692 | R28: =M28+1 -> 1.1913898 | S28: =N28+1 -> 0.97225505 | T28: =O28/O27-1 -> 0.00054008453 | U28: =P28/P27-1 -> -0.0020818174 | V28: =Q28/Q27-1 -> 0.0032357365 | W28: =R28/R27-1 -> -0.0090293222 | X28: =S28/S27-1 -> 0.0056415606 | Y28: =MAX(O$4:O28) -> 1.1809099 | Z28: =MAX(P$4:P28) -> 1.1966419 | AA28: =MAX(Q$4:Q28) -> 1.1676692 | AB28: =MAX(R$4:R28) -> 1.2078859 | AC28: =MAX(S$4:S28) -> 1.0180839 | AD28: =O28/Y28-1 -> 0 | AE28: =P28/Z28-1 -> -0.0020818174 | AF28: =Q28/AA28-1 -> 0 | AG28: =R28/AB28-1 -> -0.013657017 | AH28: =S28/AC28-1 -> -0.045014811 | AT28: 399673.SZ | AU28: 创业板50 | AV28: 0.25
A29: 43878 | B29: =[1]!thsiFinD("ths_int_chg_ratio_index",B$1,$A$4,$A29,101) -> 6.0261065 | C29: =[1]!thsiFinD("ths_int_chg_ratio_index",C$1,$A$4,$A29,101) -> 36.550928 | D29: =[1]!thsiFinD("ths_int_chg_ratio_index",D$1,$A$4,$A29,101) -> 35.483132 | E29: =[1]!thsiFinD("ths_int_chg_ratio_index",E$1,$A$4,$A29,101) -> 19.046607 | F29: =[1]!thsiFinD("ths_adjustment_nvg_ratio_fund",F$1,$A$4,$A29,101) -> 22.95887 | G29: =[1]!thsiFinD("ths_adjustment_nvg_ratio_fund",G$1,$A$4,$A29,101) -> 21.906924 | H29: =[1]!thsiFinD("ths_adjustment_nvg_ratio_fund",H$1,$A$4,$A29,101) -> 23.307692 | I29: =[1]!thsiFinD("ths_adjustment_nvg_ratio_fund",I$1,$A$4,$A29,101) -> 15.234375 | J29: =50%*K29+50%*L29 -> 0.22564329 | K29: =SUMPRODUCT(B29:E29,B$3:E$3)/100 -> 0.24276693 | L29: =SUMPRODUCT(F29:I29,F$3:I$3)/100 -> 0.20851965 | M29: =[1]!thsiFinD("ths_int_chg_ratio_index",M$1,$A$4,$A29,101)/100 -> 0.23987156 | N29: =[1]!thsiFinD("ths_int_chg_ratio_index",N$1,$A$4,$A29,101)/100 -> -0.0035773233 | O29: =J29+1 -> 1.2256433 | P29: =K29+1 -> 1.2427669 | Q29: =L29+1 -> 1.2085197 | R29: =M29+1 -> 1.2398716 | S29: =N29+1 -> 0.99642268 | T29: =O29/O28-1 -> 0.03788041 | U29: =P29/P28-1 -> 0.040711963 | V29: =Q29/Q28-1 -> 0.03498464 | W29: =R29/R28-1 -> 0.040693468 | X29: =S29/S28-1 -> 0.02485729 | Y29: =MAX(O$4:O29) -> 1.2256433 | Z29: =MAX(P$4:P29) -> 1.2427669 | AA29: =MAX(Q$4:Q29) -> 1.2085197 | AB29: =MAX(R$4:R29) -> 1.2398716 | AC29: =MAX(S$4:S29) -> 1.0180839 | AD29: =O29/Y29-1 -> 0 | AE29: =P29/Z29-1 -> 0 | AF29: =Q29/AA29-1 -> 0 | AG29: =R29/AB29-1 -> 0 | AH29: =S29/AC29-1 -> -0.021276467
A30: 43879 | B30: =[1]!thsiFinD("ths_int_chg_ratio_index",B$1,$A$4,$A30,101) -> 7.5453205 | C30: =[1]!thsiFinD("ths_int_chg_ratio_index",C$1,$A$4,$A30,101) -> 44.353375 | D30: =[1]!thsiFinD("ths_int_chg_ratio_index",D$1,$A$4,$A30,101) -> 37.231734 | E30: =[1]!thsiFinD("ths_int_chg_ratio_index",E$1,$A$4,$A30,101) -> 20.324023 | F30: =[1]!thsiFinD("ths_adjustment_nvg_ratio_fund",F$1,$A$4,$A30,101) -> 25.475752 | G30: =[1]!thsiFinD("ths_adjustment_nvg_ratio_fund",G$1,$A$4,$A30,101) -> 23.212259 | H30: =[1]!thsiFinD("ths_adjustment_nvg_ratio_fund",H$1,$A$4,$A30,101) -> 24.769231 | I30: =[1]!thsiFinD("ths_adjustment_nvg_ratio_fund",I$1,$A$4,$A30,101) -> 15.917969 | J30: =50%*K30+50%*L30 -> 0.24853708 | K30: =SUMPRODUCT(B30:E30,B$3:E$3)/100 -> 0.27363613 | L30: =SUMPRODUCT(F30:I30,F$3:I$3)/100 -> 0.22343803 | M30: =[1]!thsiFinD("ths_int_chg_ratio_index",M$1,$A$4,$A30,101)/100 -> 0.25632828 | N30: =[1]!thsiFinD("ths_int_chg_ratio_index",N$1,$A$4,$A30,101)/100 -> -0.0042758505 | O30: =J30+1 -> 1.2485371 | P30: =K30+1 -> 1.2736361 | Q30: =L30+1 -> 1.223438 | R30: =M30+1 -> 1.2563283 | S30: =N30+1 -> 0.99572415 | T30: =O30/O29-1 -> 0.018678994 | U30: =P30/P29-1 -> 0.024839087 | V30: =Q30/Q29-1 -> 0.012344335 | W30: =R30/R29-1 -> 0.013272923 | X30: =S30/S29-1 -> -0.000701035 | Y30: =MAX(O$4:O30) -> 1.2485371 | Z30: =MAX(P$4:P30) -> 1.2736361 | AA30: =MAX(Q$4:Q30) -> 1.223438 | AB30: =MAX(R$4:R30) -> 1.2563283 | AC30: =MAX(S$4:S30) -> 1.0180839 | AD30: =O30/Y30-1 -> 0 | AE30: =P30/Z30-1 -> 0 | AF30: =Q30/AA30-1 -> 0 | AG30: =R30/AB30-1 -> 0 | AH30: =S30/AC30-1 -> -0.021962587 | AT30: 产业趋势主动组合：精选2020年以来在不同产业发挥阶段对产业趋势均有捕获的基金经理，且框架稳定，长期超额出色
A31: 43880 | B31: =[1]!thsiFinD("ths_int_chg_ratio_index",B$1,$A$4,$A31,101) -> 7.2612944 | C31: =[1]!thsiFinD("ths_int_chg_ratio_index",C$1,$A$4,$A31,101) -> 45.586493 | D31: =[1]!thsiFinD("ths_int_chg_ratio_index",D$1,$A$4,$A31,101) -> 34.687887 | E31: =[1]!thsiFinD("ths_int_chg_ratio_index",E$1,$A$4,$A31,101) -> 17.635613 | F31: =[1]!thsiFinD("ths_adjustment_nvg_ratio_fund",F$1,$A$4,$A31,101) -> 24.923266 | G31: =[1]!thsiFinD("ths_adjustment_nvg_ratio_fund",G$1,$A$4,$A31,101) -> 20.601589 | H31: =[1]!thsiFinD("ths_adjustment_nvg_ratio_fund",H$1,$A$4,$A31,101) -> 22.846154 | I31: =[1]!thsiFinD("ths_adjustment_nvg_ratio_fund",I$1,$A$4,$A31,101) -> 13.378906 | J31: =50%*K31+50%*L31 -> 0.2336515 | K31: =SUMPRODUCT(B31:E31,B$3:E$3)/100 -> 0.26292822 | L31: =SUMPRODUCT(F31:I31,F$3:I$3)/100 -> 0.20437479 | M31: =[1]!thsiFinD("ths_int_chg_ratio_index",M$1,$A$4,$A31,101)/100 -> 0.23521724 | N31: =[1]!thsiFinD("ths_int_chg_ratio_index",N$1,$A$4,$A31,101)/100 -> -0.0079725468 | O31: =J31+1 -> 1.2336515 | P31: =K31+1 -> 1.2629282 | Q31: =L31+1 -> 1.2043748 | R31: =M31+1 -> 1.2352172 | S31: =N31+1 -> 0.99202745 | T31: =O31/O30-1 -> -0.011922413 | U31: =P31/P30-1 -> -0.0084073558 | V31: =Q31/Q30-1 -> -0.015581695 | W31: =R31/R30-1 -> -0.016803763 | X31: =S31/S30-1 -> -0.0037125708 | Y31: =MAX(O$4:O31) -> 1.2485371 | Z31: =MAX(P$4:P31) -> 1.2736361 | AA31: =MAX(Q$4:Q31) -> 1.223438 | AB31: =MAX(R$4:R31) -> 1.2563283 | AC31: =MAX(S$4:S31) -> 1.0180839 | AD31: =O31/Y31-1 -> -0.011922413 | AE31: =P31/Z31-1 -> -0.0084073558 | AF31: =Q31/AA31-1 -> -0.015581695 | AG31: =R31/AB31-1 -> -0.016803763 | AH31: =S31/AC31-1 -> -0.02559362 | AT31: 代码 | AU31: 基金经理 | AV31: 配比
